Workbook

Sheet 选修课表清单
A1: 编号 | B1: 课程名称 | C1: 授课老师 | D1: email | E1: 上课星期 | F1: 上课地点 | G1: 承诺书需要 | H1: 上课人数 | I1: 承诺书发放 | J1: 上课天数 | K1: 上课日期→
A2: 1 | B2: 高一美术 | C2: 刘鸿杰 | D2: ecchhs049@chhsban.edu.my | E2: Monday / 15:40~16:50 | F2: 美术室 | G2: TRUE | H2: ='高一美术-刘鸿杰师'!L3 -> 34 | I2: TRUE | J2: 2 | K2: 19/1 | L2: 2/3
A3: 2 | B3: U1A音乐 | C3: 李甄琳 | D3: ecchhs379@chhsban.edu.my | E3: Thursday / 14:30~15:40 | F3: 音乐室 | H3: ='U1A 音乐-李甄琳'!L3 -> 14 | J3: 8 | K3: 22/1 | L3: 29/1 | M3: 2/12 | N3: 26/2 | O3: 3/4 | P3: 4/9 | Q3: 11/6 | R3: 9/7
A4: 3 | B4: U1A美术 | C4: 陈彩韵 | D4: ecchhs236@chhsban.edu.my | E4: Thursday / 14:30~15:40 | F4: A406 | H4: ='U1A 美术-陈彩韵'!L3 -> 16 | J4: 2 | K4: 22/1 | L4: 29/1
A5: 4 | B5: 高一华文文学 | C5: 曾奂焜 | D5: ecchhs016@chhsban.edu.my | E5: Tuesday / 16:15~16:50 & Thursday / 15:40~16:50 | F5: A307 | G5: TRUE | H5: ='高一华文文学 曾奂焜'!L3 -> 28 | I5: TRUE | J5: 32 | K5: 20/1 | L5: 22/1 | M5: 27/1 | N5: 29/1 | O5: 3/2 | P5: 5/2 | Q5: 10/2 | R5: 12/2 | S5: 24/2 | T5: 26/2 | U5: 3/3 | V5: 5/3 | W5: 31/3 | X5: 2/4 | Y5: 7/4 | Z5: 9/4 | AA5: 14/4 | AB5: 16/4 | AC5: 21/4 | AD5: 23/4 | AE5: 28/4 | AF5: 30/4 | AG5: 5/5 | AH5: 7/5 | AI5: 12/5 | AJ5: 9/6 | AK5: 11/6 | AL5: 25/6 | AM5: 30/6 | AN5: 2/7 | AO5: 9/7 | AP5: 14/7
A6: 5 | B6: 高二华文文学 | C6: 陈静贤 | D6: ecchhs338@chhsban.edu.my | E6: Tuesday / 16:15~16:50 & Friday / 15:40~16:50 | F6: A308 | G6: TRUE | H6: ='高二华文文学-陈静贤'!L3 -> 21 | I6: TRUE | J6: 4 | K6: 20/1 | L6: 23/1 | M6: 27/1 | N6: 30/1
A7: 6 | B7: 高二美术 | C7: 刘鸿杰 | D7: ecchhs049@chhsban.edu.my | E7: Thursday / 15:40~16:50 | F7: 美术室 | G7: TRUE | H7: ='高二美术-刘鸿杰师'!L3 -> 41 | I7: TRUE | J7: 5 | K7: 22/1 | L7: 29/1 | M7: 12/2 | N7: 26/2 | O7: 5/3
A8: 7 | B8: 高一 ADDMath | C8: 温添发 | D8: ecchhs059@chhsban.edu.my | E8: Tuesday / 16:15~17:25 & Wednesday 16:15~17:25 | F8: A301 | G8: TRUE | H8: ='高一 SPM AddMath 温添发'!L3 -> 32 | I8: TRUE | J8: 14 | K8: 20/1 | L8: 21/1 | M8: 27/1 | N8: 28/1 | O8: 3/2 | P8: 4/2 | Q8: 10/2 | R8: 11/2 | S8: 24/2 | T8: 25/2 | U8: 3/3 | V8: 4/3 | W8: 31/3 | X8: 1/4
A9: 8 | B9: 高二 ADDMath | C9: 萧子良 | D9: ecchhs024@chhsban.edu.my | E9: Monday / 15:40 ~ 16:50 & Wednesday 16:15~16:50 | F9: A303 | G9: TRUE | H9: ='高二 SPM AddMath 萧子良'!L3 -> 19 | I9: TRUE | J9: 27 | K9: 19/1 | L9: 21/1 | M9: 26/1 | N9: 28/1 | O9: 4/2 | P9: 23/2 | Q9: 25/2 | R9: 2/3 | S9: 4/3 | T9: 30/3 | U9: 1/4 | V9: 4/4 | W9: 8/4 | X9: 13/4 | Y9: 15/4 | Z9: 20/4 | AA9: 22/4 | AB9: 27/4 | AC9: 29/4 | AD9: 4/5 | AE9: 6/5 | AF9: 11/5 | AG9: 8/6 | AH9: 10/6 | AI9: 24/6 | AJ9: 29/6 | AK9: 1/7
A10: 9 | B10: U2A美术 | C10: 刘鸿杰 | D10: ecchhs049@chhsban.edu.my | E10: Wednesday / 14:30~15:40 | F10: A405 | H10: ='U2A美术-刘鸿杰'!L3 -> 16 | J10: 5 | K10: 21/1 | L10: 28/1 | M10: 11/2 | N10: 25/2 | O10: 4/3
A11: 10 | B11: U2A音乐 | C11: 黄妍薇 | D11: ecchhs287@chhsban.edu.my | E11: Wednesday / 14:30~15:40 | F11: 音乐室 | H11: ='U2A音乐-黄妍薇'!L3 -> 15 | J11: 0
A12: 11 | B12: S3A电脑 | C12: 吴丽丽 | D12: lilychhs@chhsban.edu.my | E12: Friday / 11:15~12:25 | F12: 电脑教室 | H12: ='S3A电脑 吴丽丽'!L3 -> 11 | J12: 16 | K12: 23/1 | L12: 30/1 | M12: 27/2 | N12: 6/3 | O12: 4/3 | P12: 10/4 | Q12: 17/4 | R12: 24/4 | S12: 8/5 | T12: 11/6 | U12: 19/6 | V12: 26/6 | W12: 3/7 | X12: 10/7 | Y12: 17/7 | Z12: 24/7
A13: 12 | B13: S3B电脑 | C13: 吴丽丽 | D13: lilychhs@chhsban.edu.my | E13: Friday / 11:15~12:25 | F13: 电脑教室 | H13: ='S3B电脑 吴丽丽'!L3 -> 7 | J13: 16 | K13: 23/1 | L13: 30/1 | M13: 27/2 | N13: 6/3 | O13: 3/4 | P13: 10/4 | Q13: 17/4 | R13: 24/4 | S13: 8/5 | T13: 12/6 | U13: 19/6 | V13: 26/6 | W13: 3/7 | X13: 10/7 | Y13: 17/7 | Z13: 24/7
A14: 13 | B14: C3A电脑 | C14: 吴丽丽 | D14: lilychhs@chhsban.edu.my | E14: Tuesday / 15:05~15:40 & Monday / 10:05~11:15 | F14: 电脑教室 | H14: ='C3A电脑 吴丽丽'!L3 -> 9 | J14: 34 | K14: 19/1 | L14: 20/1 | M14: 26/1 | N14: 27/1 | O14: 3/2 | P14: 24/2 | Q14: 2/3 | R14: 3/3 | S14: 9/3 | T14: 6/4 | U14: 7/4 | V14: 13/4 | W14: 14/4 | X14: 20/4 | Y14: 21/4 | Z14: 27/4 | AA14: 28/4 | AB14: 4/5 | AC14: 5/5 | AD14: 12/5 | AE14: 8/6 | AF14: 9/6 | AG14: 15/6 | AH14: 16/6 | AI14: 22/6 | AJ14: 29/6 | AK14: 30/6 | AL14: 13/7 | AM14: 14/7 | AN14: 20/7 | AO14: 21/7 | AP14: 27/7 | AQ14: 4/8 | AR14: 6/8
A15: 14 | B15: C3B电脑 | C15: 吴丽丽 | D15: lilychhs@chhsban.edu.my | E15: Tuesday / 15:05~15:40 & Monday / 10:05~11:15 | F15: 电脑教室 | H15: ='C3B电脑 吴丽丽'!L3 -> 11 | J15: 32 | K15: 19/1 | L15: 20/1 | M15: 26/1 | N15: 27/1 | O15: 2/2 | P15: 24/2 | Q15: 2/3 | R15: 3/3 | S15: 9/3 | T15: 6/4 | U15: 7/4 | V15: 13/4 | W15: 14/4 | X15: 20/4 | Y15: 21/4 | Z15: 27/428/4 | AA15: 4/5 | AB15: 5/5 | AC15: 8/6 | AD15: 9/6 | AE15: 15/6 | AF15: 15/6 | AG15: 22/6 | AH15: 29/6 | AI15: 30/6 | AJ15: 13/7 | AK15: 14/7 | AL15: 20/7 | AM15: 21/7 | AN15: 27/7 | AO15: 4/8 | AP15: 6/8
A16: 15 | B16: C3C电脑 | C16: 吴丽丽 | D16: lilychhs@chhsban.edu.my | E16: Thursday / 15:05~15:40 & Tuesday / 10:05~11:15 | F16: 电脑教室 | H16: ='C3C电脑 吴丽丽'!L3 -> 17 | J16: 33 | K16: 20/1 | L16: 22/1 | M16: 27/1 | N16: 29/1 | O16: 3/2 | P16: 5/2 | Q16: 2/10 | R16: 12/2 | S16: 26/2 | T16: 3/3 | U16: 7/4 | V16: 9/4 | W16: 14/4 | X16: 21/4 | Y16: 23/4 | Z16: 28/4 | AA16: 30/4 | AB16: 5/5 | AC16: 7/5 | AD16: 12/5 | AE16: 9/6 | AF16: 11/6 | AG16: 16/9 | AH16: 18/6 | AI16: 25/6 | AJ16: 30/6 | AK16: 2/7 | AL16: 9/7 | AM16: 14/7 | AN16: 21/7 | AO16: 23/7 | AP16: 4/8 | AQ16: 6/8
A17: 16 | B17: C3D电脑 | C17: 吴丽丽 | D17: lilychhs@chhsban.edu.my | E17: Thursday / 15:05~15:40 & Tuesday / 10:05~11:15 | F17: 电脑教室 | H17: ='C3D电脑 吴丽丽'!L3 -> 12 | J17: 33 | K17: 20/1 | L17: 22/1 | M17: 27/1 | N17: 29/1 | O17: 2/3 | P17: 2/5 | Q17: 2/10 | R17: 12/2 | S17: 26/2 | T17: 3/3 | U17: 7/4 | V17: 9/4 | W17: 14/4 | X17: 21/4 | Y17: 23/4 | Z17: 28/4 | AA17: 30/4 | AB17: 5/5 | AC17: 7/5 | AD17: 12/5 | AE17: 9/6 | AF17: 11/6 | AG17: 16/9 | AH17: 16/9 | AI17: 26/6 | AJ17: 30/6 | AK17: 2/7 | AL17: 9/7 | AM17: 14/7 | AN17: 21/7 | AO17: 21/7 | AP17: 4/8 | AQ17: 6/8
A18: 17 | B18: C3E电脑 | C18: 吴丽丽 | D18: lilychhs@chhsban.edu.my | E18: Monday / 15:05~15:40 & Thursday / 10:05~11:15 | F18: 电脑教室 | H18: ='C3E电脑 吴丽丽'!L3 -> 9 | J18: 34 | K18: 19/1 | L18: 22/1 | M18: 26/1 | N18: 29/1 | O18: 2/5 | P18: 12/2 | Q18: 23/2 | R18: 2/3 | S18: 5/3 | T18: 9/3 | U18: 30/3 | V18: 6/4 | W18: 9/4 | X18: 13/4 | Y18: 20/4 | Z18: 23/4 | AA18: 27/4 | AB18: 30/4 | AC18: 4/5 | AD18: 7/5 | AE18: 8/6 | AF18: 11/6 | AG18: 15/619/6 | AH18: 22/6 | AI18: 25/6 | AJ18: 29/6 | AK18: 2/7 | AL18: 9/7 | AM18: 13/7 | AN18: 16/7 | AO18: 20/7 | AP18: 20/7 | AQ18: 23/7 | AR18: 6/8
A19: 18 | B19: C3F电脑 | C19: 吴丽丽 | D19: lilychhs@chhsban.edu.my | E19: Monday / 15:05~15:40 & Thursday / 10:05~11:15 | F19: 电脑教室 | H19: ='C3F电脑 吴丽丽'!L3 -> 10 | J19: 33 | K19: 19/1 | L19: 22/1 | M19: 26/1 | N19: 29/1 | O19: 2/5 | P19: 12/2 | Q19: 23/2 | R19: 2/3 | S19: 5/3 | T19: 9/3 | U19: 30/3 | V19: 6/4 | W19: 9/4 | X19: 13/4 | Y19: 20/4 | Z19: 23/4 | AA19: 27/4 | AB19: 30/4 | AC19: 4/5 | AD19: 7/5 | AE19: 8/6 | AF19: 11/6 | AG19: 15/619/6 | AH19: 22/6 | AI19: 25/6 | AJ19: 29/6 | AK19: 2/7 | AL19: 9/7 | AM19: 13/7 | AN19: 16/7 | AO19: 20/7 | AP19: 23/7 | AQ19: 6/8
A20: 19 | B20: P. Islam | C20: ROHAYA | D20: ecchhs215@chhsban.edu.my | E20: Monday / 15:40~16:15 & Tuesday / 16:15~17:25 | F20: A309 | H20: ='P. Islam ROHAYA'!L3 -> 10 | J20: 66 | K20: 12/1 | L20: 13/1 | M20: 15/1 | N20: 19/1 | O20: 20/1 | P20: 21/1 | Q20: 26/1 | R20: 27/1 | S20: 29/1 | T20: 2/2 | U20: 2/3 | V20: 2/5 | W20: 2/9 | X20: 2/10 | Y20: 2/12 | Z20: 16/2 | AA20: 17/2 | AB20: 19/2 | AC20: 23/2 | AD20: 24/2 | AE20: 26/2 | AF20: 2/3 | AG20: 3/3 | AH20: 5/3 | AI20: 9/3 | AJ20: 3/10 | AK20: 3/12 | AL20: 16/3 | AM20: 17/3 | AN20: 19/3 | AO20: 23/3 | AP20: 24/3 | AQ20: 26/3 | AR20: 30/3 | AS20: 31/3 | AT20: 2/4 | AU20: 6/4 | AV20: 7/4 | AW20: 9/4 | AX20: 13/4 | AY20: 14/4 | AZ20: 16/4 | BA20: 20/4 | BB20: 21/4 | BC20: 23/4 | BD20: 27/4 | BE20: 28/4 | BF20: 30/4 | BG20: 4/5 | BH20: 5/5 | BI20: 7/5 | BJ20: 11/5 | BK20: 12/5 | BL20: 8/6 | BM20: 9/6 | BN20: 11/6 | BO20: 15/6 | BP20: 16/6 | BQ20: 22/6 | BR20: 23/6 | BS20: 25/6 | BT20: 29/6 | BU20: 30/6 | BV20: 2/7 | BW20: 13/7 | BX20: 16/7
A21: 20 | B21: 高三历史 | C21: 林木胜 | D21: ecchhs253@chhsban.edu.my | E21: Tuesday / 15:40~16:50 & Friday / 15:05~16:15 | F21: A304 | H21: ='高三历史 林木胜'!L3 -> 23 | J21: 4 | K21: 20/1 | L21: 23/1 | M21: 27/1 | N21: 30/1
A22: 21 | B22: 高三地理 | C22: 杨傚因 | D22: ecchhs261@chhsban.edu.my | E22: Monday / 15:40~16:50 & Thursday /15:50~16:50 | F22: A305 | H22: ='高三地理 杨傚因'!L3 -> 14 | J22: 33 | K22: 19/1 | L22: 22/1 | M22: 26/1 | N22: 2/2 | O22: 5/2 | P22: 12/2 | Q22: 23/2 | R22: 26/2 | S22: 2/3 | T22: 5/3 | U22: 30/3 | V22: 2/4 | W22: 6/4 | X22: 9/4 | Y22: 13/4 | Z22: 16/4 | AA22: 20/4 | AB22: 23/4 | AC22: 27/4 | AD22: 4/5 | AE22: 7/5 | AF22: 11/5 | AG22: 8/6 | AH22: 11/6 | AI22: 22/6 | AJ22: 25/6 | AK22: 29/6 | AL22: 2/7 | AM22: 9/7 | AN22: 13/7 | AO22: 16/7 | AP22: 20/7 | AQ22: 27/7
A23: 22 | B23: 高三美术 | C23: 陈天成、陈欣恩 | D23: ecchhs212@chhsban.edu.my | E23: Wednesday 15:40~17:25 | F23: 美术室 | H23: ='高三美术 陈天成'!L3 -> 29 | J23: 19 | K23: 28/1 | L23: 4/2 | M23: 11/2 | N23: 25/2 | O23: 4/3 | P23: 1/4 | Q23: 8/4 | R23: 15/4 | S23: 22/4 | T23: 29/4 | U23: 6/5 | V23: 13/5 | W23: 10/6 | X23: 23/6 | Y23: 1/7 | Z23: 8/7 | AA23: 15/7 | AB23: 22/7 | AC23: 29/7
A24: 23 | B24: 初一数学校队 | C24: 萧子良 | D24: ecchhs024@chhsban.edu.my | E24: Tuesday / 15:40~16:50 | F24: A306 | H24: ='初一数学校队 萧子良'!L3 -> 12 | J24: 13 | K24: 9/2 | L24: 16/2 | M24: 23/2 | N24: 31/3 | O24: 7/4 | P24: 14/4 | Q24: 21/4 | R24: 28/4 | S24: 5/5 | T24: 9/6 | U24: 16/6 | V24: 23/6 | W24: 30/6
A25: 24 | B25: 初二、三数学校队 | C25: 刘汶兴 | E25: Thursday / 15:40~16:50 | F25: A306 | H25: ='初二、初三数学校队 刘汶兴'!L3 -> 30 | J25: 13 | K25: 3/2 | L25: 10/2 | M25: 24/2 | N25: 31/3 | O25: 7/4 | P25: 14/4 | Q25: 21/4 | R25: 28/4 | S25: 5/5 | T25: 9/6 | U25: 16/6 | V25: 23/6 | W25: 30/6
A26: 25 | B26: 高一数学校队 | C26: 蔡康壮 | E26: Thursday / 15:40~16:50 | F26: A306 | H26: ='高一数学校队 蔡康壮'!L3 -> 7 | J26: 18 | K26: 5/2 | L26: 12/2 | M26: 26/2 | N26: 5/3 | O26: 2/4 | P26: 9/4 | Q26: 16/4 | R26: 23/4 | S26: 30/4 | T26: 11/6 | U26: 18/6 | V26: 25/6 | W26: 2/7 | X26: 9/7 | Y26: 16/7 | Z26: 23/7 | AA26: 30/7 | AB26: 6/8
A27: 26 | B27: 高二、三数学校队 | C27: 蔡康壮 | E27: Friday / 15:40~16:50 | F27: A306 | H27: ='高二、高三数学校队 蔡康壮'!L3 -> 29 | J27: 15 | K27: 6/2 | L27: 26/2 | M27: 6/3 | N27: 3/4 | O27: 10/4 | P27: 17/4 | Q27: 24/4 | R27: 12/6 | S27: 19/6 | T27: 26/6 | U27: 3/7 | V27: 10/7 | W27: 17/7 | X27: 31/7 | Y27: 7/8

Sheet Sheet8

Sheet 模板
A1: 科目： | C1: P. Islam | H1: 男 | J1: 女
A2: 时段: | C2: ='选修课表清单'!E20 -> Monday / 15:40~16:15 & Tuesday / 16:15~17:25 | G2: 走/宿 | H2: L | I2: LH | J2: P | K2: PH | L2: 总计
A3: 地点： | C3: ='选修课表清单'!F20 -> A309 | G3: 人数 | H3: =COUNTIF($E:$E,"L") -> 0 | I3: =COUNTIF($E:$E,"LH") -> 0 | J3: =COUNTIF($E:$E,"P") -> 0 | K3: =COUNTIF($E:$E,"PH") -> 0 | L3: =H4+J4 -> 0
A4: 老师： | C4: ='选修课表清单'!C20 -> ROHAYA | G4: 合计 | H4: =SUM(H3:I3) -> 0 | J4: =SUM(J3:K3) -> 0
A6: No. | B6: ADM. | C6: Name | D6: 姓名 | E6: 性别 | F6: 班级 | G6: 承诺书 | H6: 日期
A7: 1
A8: 2
A9: 3
A10: 4
A11: 5
A12: 6
A13: 7
A14: 8
A15: 9
A16: 10
A17: 11
A18: 12
... A46: 40

Sheet U1A 音乐-李甄琳
A1: 科目： | C1: U1A音乐 | H1: 男 | J1: 女
A2: 时段: | C2: ='选修课表清单'!E3 -> Thursday / 14:30~15:40 | G2: 走/宿 | H2: L | I2: LH | J2: P | K2: PH | L2: 总计
A3: 地点： | C3: ='选修课表清单'!F3 -> 音乐室 | G3: 人数 | H3: =COUNTIF($E:$E,"L") -> 9 | I3: =COUNTIF($E:$E,"LH") -> 5 | J3: =COUNTIF($E:$E,"P") -> 0 | K3: =COUNTIF($E:$E,"PH") -> 0 | L3: =H4+J4 -> 14
A4: 老师： | C4: ='选修课表清单'!C3 -> 李甄琳 | G4: 合计 | H4: =SUM(H3:I3) -> 14 | J4: =SUM(J3:K3) -> 0
H5: ⬇️ | I5: "Please start entering the class dates from cell H6."
A6: No. | B6: ADM. | C6: Name | D6: 姓名 | E6: 性别 | F6: 班级 | G6: 承诺书 | H6: 22/1 | I6: 29/1 | J6: 2/12 | K6: 26/2 | L6: 3/4 | M6: 4/9 | N6: 11/6 | O6: 9/7
A7: 1 | B7: 22099 | C7: CHEONG HEIN WEI | D7: 张轩玮 | E7: LH | F7: U1A | H7: / | I7: / | J7: / | K7: / | L7: / | M7: / | N7: / | O7: /
A8: 2 | B8: 22106 | C8: LEE KAR LOK | D8: 李家乐 | E8: L | F8: U1A | H8: - | I8: / | J8: 联协 | K8: / | L8: / | M8: 公 | N8: 公 | O8: /
A9: 3 | B9: 22186 | C9: LIM JIA PAO | D9: 林家葆 | E9: L | F9: U1A | H9: / | I9: / | J9: / | K9: / | L9: / | M9: / | N9: / | O9: /
A10: 4 | B10: 22235 | C10: TAN WEE SHEN | D10: 邓炜燊 | E10: LH | F10: U1A | H10: / | I10: / | J10: 早 | K10: / | L10: / | M10: / | N10: / | O10: 转
A11: 5 | B11: 22262 | C11: TAN JIE KAI | D11: 陈诘恺 | E11: L | F11: U1A | H11: / | I11: / | J11: / | K11: / | L11: / | M11: / | N11: / | O11: /
A12: 6 | B12: 22280 | C12: JUSTIN WONG WEI XUEN | D12: 黄玮翾 | E12: LH | F12: U1A | H12: / | I12: / | J12: / | K12: / | L12: / | M12: / | N12: / | O12: /
A13: 7 | B13: 22443 | C13: LIOW WEN LOONG | D13: 廖文龙 | E13: L | F13: U1A | H13: / | I13: / | J13: / | K13: / | L13: / | M13: / | N13: / | O13: /
A14: 8 | B14: 22559 | C14: CHOW WEN BIN | D14: 鄒文斌 | E14: L | F14: U1A | H14: / | I14: / | J14: / | K14: / | L14: / | M14: / | N14: 0 | O14: /
A15: 9 | B15: 23159 | C15: LEE CHING SIANG | D15: 李庆祥 | E15: LH | F15: U1A | H15: / | I15: / | J15: / | K15: / | L15: / | M15: / | N15: / | O15: /
A16: 10 | B16: 23401 | C16: ZENG SHANG NAN | D16: 曾尚南 | E16: L | F16: U1A | H16: / | I16: / | J16: / | K16: / | L16: / | M16: / | N16: / | O16: /
A17: 11 | B17: 23457 | C17: OSCAR SIOW JING YANG | D17: 萧靖洋 | E17: L | F17: U1A | H17: / | I17: / | J17: / | K17: / | L17: / | M17: / | N17: 0 | O17: /
A18: 12 | B18: 23521 | C18: LIM YOU YING | D18: 林有營 | E18: LH | F18: U1A | H18: / | I18: / | J18: / | K18: / | L18: / | M18: / | N18: / | O18: /
A19: 13 | B19: 23544 | C19: WONG CHIN LEONG | D19: 黃俊良 | E19: L | F19: U1A | H19: / | I19: / | J19: / | K19: / | L19: / | M19: / | N19: / | O19: /
A20: 14 | B20: 26480 | C20: WAY YU YANG | D20: 韦宇阳 | E20: L | F20: U1A | H20: / | I20: / | J20: / | K20: / | L20: / | M20: / | N20: / | O20: /
A22: 16
A23: 17
A24: 18
A25: 19
A26: 20
A27: 21
A28: 22
A29: 23
A30: 24
A31: 25
A32: 26
A33: 27
... A46: 40

Sheet 初一数学校队 萧子良
A1: 科目： | C1: 初一数学校队 | H1: 男 | J1: 女
A2: 时段: | C2: ='选修课表清单'!E24 -> Tuesday / 15:40~16:50 | G2: 走/宿 | H2: L | I2: LH | J2: P | K2: PH | L2: 总计
A3: 地点： | C3: ='选修课表清单'!F24 -> A306 | G3: 人数 | H3: =COUNTIF($E:$E,"L") -> 5 | I3: =COUNTIF($E:$E,"LH") -> 4 | J3: =COUNTIF($E:$E,"P") -> 3 | K3: =COUNTIF($E:$E,"PH") -> 0 | L3: =H4+J4 -> 12
A4: 老师： | C4: ='选修课表清单'!C24 -> 萧子良 | G4: 合计 | H4: =SUM(H3:I3) -> 9 | J4: =SUM(J3:K3) -> 3
H5: ⬇️ | I5: "Please start entering the class dates from cell H6."
A6: No. | B6: ADM. | C6: Name | D6: 姓名 | E6: 性别 | F6: 班级 | G6: 承诺书 | H6: 9/2 | I6: 16/2 | J6: 23/2 | K6: 31/3 | L6: 7/4 | M6: 14/4 | N6: 21/4 | O6: 28/4 | P6: 5/5 | Q6: 9/6 | R6: 16/6 | S6: 23/6 | T6: 30/6 | U6: 14/7 | V6: 21/7 | W6: 28/7 | X6: 4/8 | Y6: 11/8 | Z6: 18/8 | AA6: 8/9 | AB6: 15/9 | AC6: 22/9 | AD6: 29/9
A7: 1 | B7: 26118 | C7: TEE WEI HNG | D7: 郑炜衡 | E7: L | F7: J1A | H7: 事 | I7: 1 | J7: 1 | K7: 1 | L7: 1 | M7: 1 | N7: 1 | O7: 1 | P7: 1 | Q7: 1 | R7: 1 | S7: 1 | T7: 1 | U7: 1 | V7: 1 | W7: 1 | X7: 1 | Y7: 1 | Z7: 1 | AA7: 1 | AB7: 1 | AC7: 1 | AD7: 1
A8: 2 | B8: 26124 | C8: LOW SHI XUN | D8: 刘世勋 | E8: L | F8: J1A | H8: 1 | I8: 1 | J8: 1 | K8: 1 | L8: 1 | M8: 1 | N8: 1 | O8: 1 | P8: 1 | Q8: 1 | R8: 1 | S8: 1 | T8: 1 | U8: 1 | V8: 1 | W8: 1 | X8: 1 | Y8: 1 | Z8: 1 | AA8: 病 | AB8: 1 | AC8: 1 | AD8: 1
A9: 3 | B9: 26484 | C9: CHIA JOHNSON | D9: 谢骏森 | E9: L | F9: J1A | H9: 1 | I9: 1 | J9: 1 | K9: 1 | L9: 1 | M9: 1 | N9: 1 | O9: 1 | P9: 1 | Q9: 1 | R9: 1 | S9: 1 | T9: 1 | U9: 1 | V9: 1 | W9: 1 | X9: 1 | Y9: 1 | Z9: 1 | AA9: 1 | AB9: 1 | AC9: 1 | AD9: 1
A10: 4 | B10: 26007 | C10: TAN WEI QI | D10: 陈微绮 | E10: P | F10: J1B | H10: 1 | I10: 1 | J10: 1 | K10: 1 | L10: 1 | M10: 1 | N10: 1 | O10: 1 | P10: 1 | Q10: 1 | R10: 1 | S10: 1 | T10: 1 | U10: 1 | V10: 1 | W10: 1 | X10: 1 | Y10: 1 | Z10: 1 | AA10: 1 | AB10: 1 | AC10: 1 | AD10: 1
A11: 5 | B11: 26015 | C11: LEE YU HONG | D11: 李昱宏 | E11: LH | F11: J1B | H11: 1 | I11: 1 | J11: 1 | K11: 1 | L11: 1 | M11: 1 | N11: 1 | O11: 1 | P11: 1 | Q11: 1 | R11: 1 | S11: 1 | T11: 1 | U11: 1 | V11: 1 | W11: 1 | X11: 1 | Y11: 1 | Z11: 1 | AA11: 1 | AB11: 1 | AC11: 1 | AD11: 1
A12: 6 | B12: 26016 | C12: SIOW YI QING | D12: 萧逸晴 | E12: P | F12: J1B | H12: 1 | I12: 1 | J12: 1 | K12: 1 | L12: 1 | M12: 1 | N12: 1 | O12: 1 | P12: 1 | Q12: 1 | R12: 1 | S12: 1 | T12: 1 | U12: 1 | V12: 1 | W12: 1 | X12: 1 | Y12: 1 | Z12: 1 | AA12: 1 | AB12: 1 | AC12: 1 | AD12: 1
A13: 7 | B13: 26026 | C13: LOW KEH ENG | D13: 刘可恩 | E13: P | F13: J1B | H13: 1 | I13: 1 | J13: 1 | K13: 1 | L13: 1 | M13: 1 | N13: 1 | O13: 1 | P13: 1 | Q13: 病 | R13: 病 | S13: 1 | T13: 1 | U13: 1 | V13: 1 | W13: 1 | X13: 1 | Y13: 1 | Z13: 1 | AA13: 1 | AB13: 1 | AC13: 1 | AD13: 1
A14: 8 | B14: 26066 | C14: CHONG KWOK SOON | D14: 庄国舜 | E14: L | F14: J1B | H14: 1 | I14: 1 | J14: 1 | K14: 1 | L14: 1 | M14: 1 | N14: 1 | O14: 1 | P14: 1 | Q14: 1 | R14: 1 | S14: 1 | T14: 1 | U14: 1 | V14: 1 | W14: 1 | X14: 1 | Y14: 1 | Z14: 1 | AA14: 1 | AB14: 1 | AC14: 1 | AD14: 1
A15: 9 | B15: 26077 | C15: LIM KAI SEN | D15: 林楷森 | E15: J1B | F15: J1B | H15: 1 | I15: 1 | J15: 1 | K15: 1 | L15: 1 | M15: 1 | N15: 1 | O15: 1 | P15: 1 | Q15: 1 | R15: 1 | S15: 1 | T15: 1 | U15: 1 | V15: 1 | W15: 病 | X15: 1 | Y15: 1 | Z15: 1 | AA15: 1 | AB15: 1 | AC15: 1 | AD15: 1
A16: 10 | B16: 26321 | C16: MOK YU HIN | D16: 莫雨轩 | E16: LH | F16: J1B | H16: 1 | I16: 1 | J16: 1 | K16: 1 | L16: 1 | M16: 1 | N16: 1 | O16: 1 | P16: 1 | Q16: 1 | R16: 1 | S16: 1 | T16: 1 | U16: 1 | V16: 1 | W16: 1 | X16: 1 | Y16: 1 | Z16: 1 | AA16: 1 | AB16: 1 | AC16: 1 | AD16: 1
A17: 11 | B17: 26105 | C17: CHIN YING SHENG | D17: 陈颖晟 | E17: L | F17: J1C | H17: 1 | I17: 1 | J17: 1 | K17: 1 | L17: 1 | M17: 1 | N17: 1 | O17: 1 | P17: 1 | Q17: 1 | R17: 1 | S17: 1 | T17: 1 | U17: 1 | V17: 1 | W17: 1 | X17: 1 | Y17: 1 | Z17: 1 | AA17: 1 | AB17: 1 | AC17: 1 | AD17: 1
A18: 12 | B18: 26002 | C18: LEE YONG YI | D18: 李永毅 | E18: LH | F18: J1D | H18: 1 | I18: 1 | J18: 1 | K18: 1 | L18: 1 | M18: 1 | N18: 1 | O18: 1 | P18: 1 | Q18: 1 | R18: 1 | S18: 1 | T18: 1 | U18: 1 | V18: 1 | W18: 1 | X18: 1 | Y18: 1 | Z18: 1 | AA18: 1 | AB18: 1 | AC18: 1 | AD18: 1
A19: 13 | B19: 26032 | C19: LOO JIA YOU | D19: 卢嘉佑 | E19: LH | F19: J1D | H19: 1 | I19: 1 | J19: 1 | K19: 1 | L19: 1 | M19: 1 | N19: 1 | O19: 1 | P19: 1 | Q19: 1 | R19: 1 | S19: 1 | T19: 1 | U19: 1 | V19: 1 | W19: 1 | X19: 1 | Y19: 1 | Z19: 1 | AA19: 病 | AB19: 病 | AC19: 1 | AD19: 1
A20: 14
A22: 16
A23: 17
A24: 18
A25: 19
A26: 20
A27: 21
A28: 22
A29: 23
A30: 24
A31: 25
A32: 26
... A46: 40

Sheet 初二、初三数学校队 刘汶兴
A1: 科目： | C1: 初二、三数学校队 | H1: 男 | J1: 女
A2: 时段: | C2: ='选修课表清单'!E25 -> Thursday / 15:40~16:50 | G2: 走/宿 | H2: L | I2: LH | J2: P | K2: PH | L2: 总计
A3: 地点： | C3: ='选修课表清单'!F25 -> A306 | G3: 人数 | H3: =COUNTIF($E:$E,"L") -> 9 | I3: =COUNTIF($E:$E,"LH") -> 11 | J3: =COUNTIF($E:$E,"P") -> 9 | K3: =COUNTIF($E:$E,"PH") -> 1 | L3: =H4+J4 -> 30
A4: 老师： | C4: ='选修课表清单'!C25 -> 刘汶兴 | G4: 合计 | H4: =SUM(H3:I3) -> 20 | J4: =SUM(J3:K3) -> 10
H5: ⬇️ | I5: "Please start entering the class dates from cell H6."
A6: No. | B6: ADM. | C6: Name | D6: 姓名 | E6: 性别 | F6: 班级 | G6: 承诺书 | H6: 3/2 | I6: 10/2 | J6: 24/2 | K6: 31/3 | L6: 7/4 | M6: 14/4 | N6: 21/4 | O6: 28/4 | P6: 5/5 | Q6: 9/6 | R6: 16/6 | S6: 23/6 | T6: 30/6 | U6: 21/7 | V6: 28/7
A7: 1 | B7: 25122 | C7: CHAN SHIN EE | D7: 陈星妮 | E7: P | F7: J2A | H7: 1 | I7: 1 | J7: 1 | K7: 1 | L7: 1 | M7: 1 | N7: 1 | O7: 1 | P7: 1 | Q7: 1 | R7: 1 | S7: 1 | T7: 1 | U7: 1 | V7: 1
A8: 2 | B8: 25183 | C8: NG CHEN HOU | D8: 黄诚皓 | E8: L | F8: J2A | H8: 1 | I8: 1 | J8: 1 | K8: 1 | L8: 1 | M8: 1 | N8: 1 | O8: 1 | P8: 0 | Q8: 1 | R8: 1 | S8: 1 | T8: 1 | U8: 1 | V8: 1
A9: 3 | B9: 25428 | C9: NG JING KAI | D9: 黄靖凯 | E9: LH | F9: J2A | H9: 1 | I9: 1 | J9: 1 | K9: 1 | L9: 1 | M9: 1 | N9: 1 | O9: 1 | P9: 1 | Q9: 1 | R9: 1 | S9: 1 | T9: 1 | U9: 1 | V9: 1
A10: 4 | B10: 25044 | C10: KUEK CHEN YUN | D10: 郭丞云 | E10: L | F10: J2A | H10: 1 | I10: 1 | J10: 1 | K10: 1 | L10: 1 | M10: 1 | N10: 1 | O10: 1 | P10: 0 | Q10: 1 | R10: 1 | S10: 1 | T10: 1 | U10: 0 | V10: 1
A11: 5 | B11: 25193 | C11: KWANG RUI HAN | D11: 关芮涵 | E11: P | F11: J2A | H11: 1 | I11: 1 | J11: 病 | K11: 1 | L11: 1 | M11: 1 | N11: 1 | O11: 1 | P11: 1 | Q11: 1 | R11: 1 | S11: 1 | T11: 1 | U11: 1 | V11: 1
A12: 6 | B12: 25198 | C12: HEW GUAN SHEN | D12: 邱冠燊 | E12: L | F12: J2B | H12: 1 | I12: 1 | J12: 1 | K12: 1 | L12: 1 | M12: 1 | N12: 1 | O12: 1 | P12: 1 | Q12: 1 | R12: 1 | S12: 1 | T12: 1 | U12: 1 | V12: 1
A13: 7 | B13: 25017 | C13: LEE LOK HIN | D13: 李乐谦 | E13: L | F13: J2B | H13: 1 | I13: 1 | J13: 1 | K13: 1 | L13: 1 | M13: 1 | N13: 1 | O13: 1 | P13: 1 | Q13: 1 | R13: 1 | S13: 1 | T13: 1 | U13: 1 | V13: 1
A14: 8 | B14: 25151 | C14: YONG JIT WEI | D14: 杨佶沩 | E14: LH | F14: J2B | H14: 1 | I14: 1 | J14: 1 | K14: 1 | L14: 1 | M14: 1 | N14: 1 | O14: 1 | P14: 1 | Q14: 1 | R14: 1 | S14: 1 | T14: 1 | U14: 1 | V14: 1
A15: 9 | B15: 25077 | C15: THAM CHEN-MING | D15: 谭丞洺 | E15: LH | F15: J2C | H15: 1 | I15: 1 | J15: 1 | K15: 1 | L15: 1 | M15: 1 | N15: 1 | O15: 1 | P15: 1 | Q15: 1 | R15: 1 | S15: 病 | T15: 病 | U15: 1 | V15: 1
A16: 10 | B16: 25028 | C16: CHEN HAO YANG | D16: 陈浩扬 | E16: LH | F16: J2C | H16: 1 | I16: 1 | J16: 1 | K16: 1 | L16: 1 | M16: 1 | N16: 1 | O16: 1 | P16: 1 | Q16: 1 | R16: 1 | S16: 1 | T16: 1 | U16: 1 | V16: 1
A17: 11 | B17: 25124 | C17: YAP HOI MING | D17: 叶海铭 | E17: LH | F17: J2C | H17: 1 | I17: 1 | J17: 1 | K17: 1 | L17: 1 | M17: 1 | N17: 1 | O17: 1 | P17: 1 | Q17: 1 | R17: 1 | S17: 1 | T17: 1 | U17: 1 | V17: 1
A18: 12 | B18: 25189 | C18: HONG YU HUAN | D18: 王玉环 | E18: P | F18: J2C | H18: 1 | I18: 1 | J18: 1 | K18: 1 | L18: 1 | M18: 1 | N18: 1 | O18: 1 | P18: 0 | Q18: 1 | R18: 1 | S18: 1 | T18: 1 | U18: 1 | V18: 1
A19: 13 | B19: 25031 | C19: LIM YUN XI | D19: 林蕴晞 | E19: P | F19: J2C | H19: 1 | I19: 公 | J19: 1 | K19: 1 | L19: 1 | M19: 1 | N19: 1 | O19: 1 | P19: 1 | Q19: 1 | R19: 1 | S19: 1 | T19: 1 | U19: 1 | V19: 1
A20: 14 | B20: 25005 | C20: LAI XIN YUU | D20: 黎心瑜 | E20: P | F20: J2C | H20: 1 | I20: 1 | J20: 1 | K20: 1 | L20: 1 | M20: 1 | N20: 1 | O20: 1 | P20: 1 | Q20: 1 | R20: 1 | S20: 1 | T20: 1 | U20: 1 | V20: 1
A21: 15 | B21: 25153 | C21: NG LI XUAN | D21: 吴俐萱 | E21: P | F21: J2D | H21: 1 | I21: 1 | J21: 1 | K21: 1 | L21: 1 | M21: 1 | N21: 1 | O21: 1 | P21: 1 | Q21: 1 | R21: 1 | S21: 1 | T21: 1 | U21: 0 | V21: 1
A22: 16 | B22: 25026 | C22: LIM YING XI | D22: 林盈希 | E22: P | F22: J2D | H22: 1 | I22: 1 | J22: 1 | K22: 1 | L22: 1 | M22: 1 | N22: 1 | O22: 1 | P22: 1 | Q22: 1 | R22: 1 | S22: 1 | T22: 1 | U22: 1 | V22: 1
A23: 17 | B23: 25119 | C23: YAP CHONG KIAT | D23: 叶忠杰 | E23: LH | F23: J2D | H23: 1 | I23: 1 | J23: 1 | K23: 1 | L23: 1 | M23: 1 | N23: 1 | O23: 1 | P23: 1 | Q23: 1 | R23: 1 | S23: 1 | T23: 1 | U23: 1 | V23: 1
A24: 18 | B24: 25081 | C24: LEE TZEN YAO | D24: 李振耀 | E24: LH | F24: J2D | H24: 1 | I24: 1 | J24: 1 | K24: 1 | L24: 0 | M24: 1 | N24: 1 | O24: 1 | P24: 1 | Q24: 1 | R24: 1 | S24: 1 | T24: 1 | U24: 0 | V24: 1
A25: 19 | B25: 24003 | C25: TERENCE HOO JON YONG | D25: 许竣阳 | E25: L | F25: J3A | H25: 1 | I25: 1 | J25: 1 | K25: 1 | L25: 1 | M25: 1 | N25: 1 | O25: 1 | P25: 1 | Q25: 1 | R25: 1 | S25: 1 | T25: 1 | U25: 1 | V25: 1
A26: 20 | B26: 24028 | C26: ANGUS SOO YI KANG | D26: 苏逸康 | E26: L | F26: J3A | H26: 1 | I26: 1 | J26: 1 | K26: 1 | L26: 1 | M26: 1 | N26: 1 | O26: 1 | P26: 1 | Q26: 1 | R26: 1 | S26: 1 | T26: 1 | U26: 1 | V26: 1
A27: 21 | B27: 24203 | C27: LIEW SING HONG | D27: 刘胜鸿 | E27: LH | F27: J3A | H27: 1 | I27: 1 | J27: 1 | K27: 1 | L27: 1 | M27: 1 | N27: 1 | O27: 1 | P27: 1 | Q27: 1 | R27: 1 | S27: 1 | T27: 1 | U27: 1 | V27: 1
A28: 22 | B28: 24001 | C28: SIOW YI CHEN | D28: 萧逸辰 | E28: L | F28: J3B | H28: 1 | I28: 1 | J28: 1 | K28: 1 | L28: 1 | M28: 1 | N28: 1 | O28: 1 | P28: 1 | Q28: 1 | R28: 1 | S28: 1 | T28: 1 | U28: 1 | V28: 1
A29: 23 | B29: 24177 | C29: LIN HAO YI | D29: 林皓宇 | E29: LH | F29: J3B | H29: x | I29: 1 | J29: 1 | K29: 1 | L29: 1 | M29: 1 | N29: 1 | O29: 1 | P29: 1 | Q29: 1 | R29: 1 | S29: 1 | T29: 1 | U29: 1 | V29: 1
A30: 24 | B30: 24081 | C30: THAM ZHEN YOON | D30: 谭振勇 | E30: LH | F30: J3C | H30: 1 | I30: 1 | J30: 1 | K30: 1 | L30: 1 | M30: 1 | N30: 1 | O30: 1 | P30: 1 | Q30: 1 | R30: 1 | S30: 1 | T30: 1 | U30: 1 | V30: 1
A31: 25 | B31: 24437 | C31: WONG JIAN MENG | D31: 黄裕彦 | E31: L | F31: J3C | H31: 1 | I31: 1 | J31: 1 | K31: 1 | L31: 1 | M31: 1 | N31: 1 | O31: 1 | P31: 1 | Q31: 1 | R31: 1 | S31: 1 | T31: 1 | U31: 1 | V31: 1
A32: 26 | B32: 24141 | C32: LIEW YEW YANG | D32: 廖犹阳 | E32: LH | F32: J3D | H32: 1 | I32: 1 | J32: 1 | K32: 1 | L32: 1 | M32: 1 | N32: 1 | O32: 1 | P32: 1 | Q32: 1 | R32: 1 | S32: 1 | T32: 1 | U32: 1 | V32: 1
A33: 27 | B33: 24017 | C33: CHANG JUN REN | D33: 郑峻仁 | E33: L | F33: J3D | H33: 1 | I33: 1 | J33: 1 | K33: 1 | L33: 1 | M33: 1 | N33: 1 | O33: 1 | P33: 1 | Q33: 1 | R33: 1 | S33: 1 | T33: 1 | U33: 1 | V33: 1
A34: 28 | B34: 24368 | C34: GOH JIA YEE | D34: 吴佳瑜 | E34: P | F34: J3D | H34: 1 | I34: 1 | J34: 1 | K34: 1 | L34: 1 | M34: 1 | N34: 1 | O34: 1 | P34: 1 | Q34: 1 | R34: 1 | S34: 1 | T34: 1 | U34: 1 | V34: 1
A35: 29 | B35: 24358 | C35: SOLPHIA LIEWN YU QING | D35: 梁雨晴 | E35: PH | F35: J3G | H35: 1 | I35: 1 | J35: 1 | K35: 1 | L35: 1 | M35: 1 | N35: 1 | O35: 0 | P35: 1 | Q35: 1 | R35: 1 | S35: 1 | T35: 1 | U35: 1 | V35: 1
A36: 30
A37: 31
A38: 32
A39: 33
A40: 34
...

Sheet 高一数学校队 蔡康壮
A1: 科目： | C1: 高一数学校队 | H1: 男 | J1: 女
A2: 时段: | C2: ='选修课表清单'!E26 -> Thursday / 15:40~16:50 | G2: 走/宿 | H2: L | I2: LH | J2: P | K2: PH | L2: 总计
A3: 地点： | C3: ='选修课表清单'!F6 -> A308 | G3: 人数 | H3: =COUNTIF($E:$E,"L") -> 4 | I3: =COUNTIF($E:$E,"LH") -> 3 | J3: =COUNTIF($E:$E,"P") -> 0 | K3: =COUNTIF($E:$E,"PH") -> 0 | L3: =H4+J4 -> 7
A4: 老师： | C4: ='选修课表清单'!C26 -> 蔡康壮 | G4: 合计 | H4: =SUM(H3:I3) -> 7 | J4: =SUM(J3:K3) -> 0
H5: ⬇️ | I5: "Please start entering the class dates from cell H6."
A6: No. | B6: ADM. | C6: Name | D6: 姓名 | E6: 性别 | F6: 班级 | G6: 承诺书 | H6: 5/2 | I6: 12/2 | J6: 26/2 | K6: 5/3 | L6: 2/4 | M6: 9/4 | N6: 16/4 | O6: 23/4 | P6: 30/4 | Q6: 11/6 | R6: 18/6 | S6: 25/6 | T6: 2/7 | U6: 9/7 | V6: 16/7 | W6: 23/7 | X6: 30/7 | Y6: 6/8 | Z6: 13/8 | AA6: 20/8 | AB6: 27/8 | AC6: 10/9 | AD6: 17/9 | AE6: 4/9
A7: 1 | B7: 23055 | C7: LEE HONG JUN | D7: 李弘筠 | E7: LH | F7: S1A | H7: 1 | I7: 1 | J7: 1 | K7: 1 | L7: 1 | M7: 公假 | N7: 1 | O7: 1 | P7: 1 | Q7: 公假 | R7: 公假 | S7: 1 | T7: 退出
A8: 2 | B8: 23456 | C8: LOH JUN YUAN | D8: 老俊源 | E8: L | F8: S1A | H8: 事假 | I8: 1 | J8: 1 | K8: 1 | L8: 1 | M8: 公假 | N8: 1 | O8: 1 | P8: 1 | Q8: 1 | R8: 1 | S8: 1 | T8: 1 | U8: 1 | V8: 1 | W8: 1 | X8: 1 | Y8: 1 | Z8: 1 | AA8: 1 | AB8: 1 | AC8: 1 | AD8: 1 | AE8: 1
A9: 3 | B9: 23094 | C9: CHEE JING HENG | D9: 朱劲衡 | E9: L | F9: S1A | H9: 1 | I9: 1 | J9: 1 | K9: 1 | L9: 1 | M9: 1 | N9: 1 | O9: 1 | P9: 1 | Q9: 1 | R9: 1 | S9: 1 | T9: 1 | U9: 1 | V9: 1 | W9: 1 | X9: 1 | Y9: 1 | Z9: 1 | AA9: 1 | AB9: 1 | AC9: 1 | AD9: 1 | AE9: 1
A10: 4 | B10: 23061 | C10: THAM CHEN-EN | D10: 谭丞恩 | E10: LH | F10: S1B | H10: 1 | I10: 1 | J10: 1 | K10: 1 | L10: 1 | M10: 1 | N10: 1 | O10: 1 | P10: 1 | Q10: 1 | R10: 1 | S10: 1 | T10: 1 | U10: 1 | V10: 1 | W10: 1 | X10: 1 | Y10: 1 | Z10: 1 | AA10: 1 | AB10: 1 | AC10: 1 | AD10: 1 | AE10: 1
A11: 5 | B11: 23082 | C11: CHUA TIAN JIAN | D11: 蔡天坚 | E11: L | F11: S1B | H11: 1 | I11: 1 | J11: 1 | K11: 1 | L11: 1 | M11: 1 | N11: 1 | O11: 1 | P11: 1 | Q11: 1 | R11: 1 | S11: 1 | T11: 1 | U11: 1 | V11: 1 | W11: 1 | X11: 1 | Y11: 1 | Z11: 1 | AA11: 1 | AB11: 1 | AC11: 1 | AD11: 1 | AE11: 1
A12: 6 | B12: 23486 | C12: DARREN LIM JIA YI | D12: 林家毅 | E12: LH | F12: S1B | H12: 1 | I12: 1 | J12: 1 | K12: 1 | L12: 1 | M12: 1 | N12: 1 | O12: 1 | P12: 1 | Q12: 1 | R12: 1 | S12: 1 | T12: 1 | U12: 1 | V12: 1 | W12: 1 | X12: 1 | Y12: 1 | Z12: 1 | AA12: 1 | AB12: 1 | AC12: 1 | AD12: 1 | AE12: 1
A13: 7 | B13: 23070 | C13: LAM YOU JUN | D13: 林有俊 | E13: L | F13: S1B | H13: 1 | I13: 1 | J13: 1 | K13: 1 | L13: 1 | M13: 1 | N13: 1 | O13: 1 | P13: 1 | Q13: 1 | R13: 1 | S13: 1 | T13: 1 | U13: 1 | V13: 1 | W13: 1 | X13: 1 | Y13: 1 | Z13: 1 | AA13: 1 | AB13: 1 | AC13: 1 | AD13: 1 | AE13: 1
A14: 8
A15: 9
A16: 10
A17: 11
A18: 12
A19: 13
A20: 14
A22: 16
A23: 17
A24: 18
A25: 19
A26: 20
... A46: 40

Sheet 高二、高三数学校队 蔡康壮
A1: 科目： | C1: 高二、三数学校队 | H1: 男 | J1: 女
A2: 时段: | C2: ='选修课表清单'!E27 -> Friday / 15:40~16:50 | G2: 走/宿 | H2: L | I2: LH | J2: P | K2: PH | L2: 总计
A3: 地点： | C3: ='选修课表清单'!F27 -> A306 | G3: 人数 | H3: =COUNTIF($E:$E,"L") -> 12 | I3: =COUNTIF($E:$E,"LH") -> 6 | J3: =COUNTIF($E:$E,"P") -> 8 | K3: =COUNTIF($E:$E,"PH") -> 3 | L3: =H4+J4 -> 29
A4: 老师： | C4: ='选修课表清单'!C27 -> 蔡康壮 | G4: 合计 | H4: =SUM(H3:I3) -> 18 | J4: =SUM(J3:K3) -> 11
H5: ⬇️ | I5: "Please start entering the class dates from cell H6."
A6: No. | B6: AMD | C6: Name | D6: 姓名 | E6: 走宿 | F6: 班級 | G6: 承诺书 | H6: 6/2 | I6: 26/2 | J6: 6/3 | K6: 3/4 | L6: 10/4 | M6: 17/4 | N6: 24/4 | O6: 12/6 | P6: 19/6 | Q6: 26/6 | R6: 3/7 | S6: 10/7 | T6: 17/7 | U6: 31/7 | V6: 7/8 | W6: 14/8 | X6: 21/8 | Y6: 28/8 | Z6: 11/9 | AA6: 18/9
A7: 1 | B7: 22140 | C7: HEW WEN BIN | D7: 丘文彬 | E7: L | F7: S2A | H7: 1 | I7: 1 | J7: 1 | K7: 1 | L7: 1 | M7: 1 | N7: 1 | O7: 1 | P7: 1 | Q7: 1 | R7: 1 | S7: 1 | T7: 1 | V7: 1 | W7: 1 | X7: 1 | Y7: 1 | Z7: 1 | AA7: 1
A8: 2 | B8: 22017 | C8: LIM ZHI CHENG | D8: 林志诚 | E8: L | F8: S2A | H8: 1 | I8: 1 | J8: 1 | K8: 1 | L8: 病假 | M8: 1 | N8: 1 | O8: 1 | P8: 1 | Q8: 1 | R8: 1 | S8: 1 | T8: 1 | V8: 1 | W8: 1 | X8: 1 | Y8: 1 | Z8: 1 | AA8: 1
A9: 3 | B9: 22066 | C9: CHAN ZHIN HANN | D9: 陈婧涵 | E9: PH | F9: S2A | H9: 1 | I9: 1 | J9: 1 | K9: 1 | L9: 1 | M9: 1 | N9: 1 | O9: 1 | P9: 1 | Q9: 1 | R9: 1 | S9: 1 | T9: 1 | V9: 1 | W9: 1 | X9: 1 | Y9: 1 | Z9: 1 | AA9: 1
A10: 4 | B10: 22070 | C10: LEE JIA QI | D10: 李家齐 | E10: LH | F10: S2A | H10: 1 | I10: 1 | J10: 1 | K10: 1 | L10: 1 | M10: 1 | N10: 1 | O10: 1 | P10: 1 | Q10: 1 | R10: 1 | S10: 1 | T10: 1 | V10: 1 | W10: 1 | X10: 1 | Y10: 1 | Z10: 1 | AA10: 1
A11: 5 | B11: 22112 | C11: TAN GIN EAN | D11: 陈竞渊 | E11: LH | F11: S2A | H11: 1 | I11: 1 | J11: 1 | K11: 1 | L11: 1 | M11: 1 | N11: 1 | O11: 1 | P11: 1 | Q11: 1 | R11: 1 | S11: 1 | T11: 1 | V11: 1 | W11: 1 | X11: 1 | Y11: 1 | Z11: 1 | AA11: 1
A12: 6 | B12: 22257 | C12: TAN WEN KANG | D12: 陈文康 | E12: L | F12: S2B | H12: 1 | I12: 1 | J12: 1 | K12: 1 | L12: 1 | M12: 1 | N12: 1 | O12: 1 | P12: 1 | Q12: 1 | R12: 1 | S12: 1 | T12: 1 | V12: 1 | W12: 1 | X12: 1 | Y12: 1 | Z12: 1 | AA12: 1
A13: 7 | B13: 22009 | C13: PHANG JIAN YOU | D13: 彭健祐 | E13: L | F13: S2B | H13: 1 | I13: 1 | J13: 1 | K13: 1 | L13: 1 | M13: 1 | N13: 1 | O13: 1 | P13: 1 | Q13: 1 | R13: 1 | S13: 1 | T13: 1 | V13: 1 | W13: 1 | X13: 1 | Y13: 1 | Z13: 1 | AA13: 1
A14: 8 | B14: 22385 | C14: IVAN LEE SENG JUN | D14: 李诚俊 | E14: L | F14: S2B | H14: 1 | I14: 1 | J14: 1 | K14: 1 | L14: 1 | M14: 1 | N14: 1 | O14: 1 | P14: 1 | Q14: 1 | R14: 1 | S14: 1 | T14: 1 | V14: 1 | W14: 1 | X14: 1 | Y14: 1 | Z14: 1 | AA14: 1
A15: 9 | B15: 22016 | C15: LIEW YU QUAN | D15: 劉祐銓 | E15: L | F15: S2B | H15: 1 | I15: 1 | J15: 1 | K15: 1 | L15: 1 | M15: 1 | N15: 1 | O15: 1 | P15: 1 | Q15: 1 | R15: 1 | S15: 1 | T15: 1 | V15: 1 | W15: 1 | X15: 1 | Y15: 1 | Z15: 1 | AA15: 1
A16: 10 | B16: 22071 | C16: CLEMENT LIM KAI ENG | D16: 林凯恩 | E16: L | F16: S2B | H16: 1 | I16: 1 | J16: 1 | K16: 1 | L16: 1 | M16: 1 | N16: 1 | O16: 1 | P16: 1 | Q16: 1 | R16: 1 | S16: 1 | T16: 1 | V16: 1 | W16: 1 | X16: 1 | Y16: 1 | Z16: 1 | AA16: 1
A17: 11 | B17: 22339 | C17: CHONG JUN HER | D17: 章浚赫 | E17: LH | F17: S2B | H17: 1 | I17: 1 | J17: 1 | K17: 1 | L17: 1 | M17: 1 | N17: 1 | O17: 1 | P17: 1 | Q17: 1 | R17: 退出 | S17: 退出
A18: 12 | B18: 22038 | C18: TAN KAI CONG | D18: 陈楷潨 | E18: LH | F18: S2B | H18: 1 | I18: 1 | J18: 1 | K18: 1 | L18: 1 | M18: 1 | N18: 1 | O18: 1 | P18: 1 | Q18: 1 | R18: 1 | S18: 1 | T18: 1 | V18: 1 | W18: 1 | X18: 1 | Y18: 1 | Z18: 1 | AA18: 1
A19: 13 | B19: 22007 | C19: MELVA LIM QIAN TONG | D19: 林芊彤 | E19: P | F19: S2B | H19: 1 | I19: 1 | J19: 1 | K19: 1 | L19: 公假 | M19: 1 | N19: 1 | O19: 1 | P19: 1 | Q19: 1 | R19: 退出 | S19: 退出
A20: 14 | B20: 22128 | C20: CHEOK KANG XUAN | D20: 石康璇 | E20: P | F20: AC2A | H20: 1 | I20: 1 | J20: 病假 | K20: 1 | L20: 1 | M20: 1 | N20: 1 | O20: 1 | P20: 1 | Q20: 公假 | R20: 病假 | S20: 病假 | T20: 公假 | V20: 1 | W20: 1 | X20: 1 | Y20: 1 | Z20: 1 | AA20: 1
A21: 15 | B21: 22411 | C21: SEE JIA LE | D21: 徐嘉乐 | E21: LH | F21: C2A | H21: 1 | I21: 1 | J21: 1 | K21: 1 | L21: 1 | M21: 1 | N21: 1 | O21: 补考 | P21: 1 | Q21: 1 | R21: 1 | S21: 1 | T21: 1 | V21: 1 | W21: 1 | X21: 1 | Y21: 1 | Z21: 1 | AA21: 1
A22: 16 | B22: 21060 | C22: LEONG CYRENE | D22: 梁瑄凌 | E22: P | F22: S3A | H22: 1 | I22: 1 | J22: 1 | K22: 1 | L22: 1 | M22: 1 | N22: 1 | O22: 1 | P22: 1 | Q22: 1 | R22: 1 | S22: 1 | T22: 1 | U22: 1 | V22: 1 | W22: 1 | X22: 1 | Y22: 1 | Z22: 1 | AA22: 1
A23: 17 | B23: 21180 | C23: TOH YU YANG | D23: 杜育扬 | E23: LH | F23: S3A | H23: 1 | I23: 1 | J23: 1 | K23: 1 | L23: 1 | M23: 1 | N23: 1 | O23: 1 | P23: 1 | Q23: 1 | R23: 1 | S23: 1 | T23: 1 | U23: 1 | V23: 1 | W23: 1 | X23: 公假 | Y23: 1 | Z23: 1 | AA23: 1
A24: 18 | B24: 21006 | C24: POO SHI MO | D24: 符世墨 | E24: L | F24: S3A | H24: 1 | I24: 1 | J24: 1 | K24: 1 | L24: 1 | M24: 1 | N24: 1 | O24: 1 | P24: 1 | Q24: 1 | R24: 1 | S24: 1 | T24: 1 | U24: 1 | V24: 1 | W24: 1 | X24: 1 | Y24: 1 | Z24: 1 | AA24: 1
A25: 19 | B25: 21001 | C25: FOONG ZI XUAN | D25: 冯梓轩 | E25: L | F25: S3A | H25: 1 | I25: 1 | J25: 1 | K25: 1 | L25: 1 | M25: 1 | N25: 1 | O25: 1 | P25: 1 | Q25: 1 | R25: 1 | S25: 1 | T25: 1 | U25: 1 | V25: 1 | W25: 1 | X25: 1 | Y25: 1 | Z25: 1 | AA25: 1
A26: 20 | B26: 21049 | C26: LIM YUN YING | D26: 林蕴颖 | E26: P | F26: S3A | H26: 1 | I26: 1 | J26: 1 | K26: 1 | L26: 1 | M26: 1 | N26: 1 | O26: 1 | P26: 1 | Q26: 1 | R26: 1 | S26: 1 | T26: 公假 | U26: 1 | V26: 1 | W26: 街舞比赛 | X26: 1 | Y26: 1 | Z26: 1 | AA26: 1
A27: 21 | B27: 21010 | C27: RENAE LEE SZI RUI | D27: 李思睿 | E27: P | F27: S3A | H27: 1 | I27: 1 | J27: 1 | K27: 1 | L27: 1 | M27: 1 | N27: 1 | O27: 1 | P27: 1 | Q27: 1 | R27: 1 | S27: 1 | T27: 1 | U27: 1 | V27: 公假 | W27: 1 | X27: 病假 | Y27: 1 | Z27: 病假 | AA27: 病假
A28: 22 | B28: 21019 | C28: TAN YIN YAN | D28: 陈映燕 | E28: P | F28: S3A | H28: 1 | I28: 1 | J28: 1 | K28: 1 | L28: 1 | M28: 1 | N28: 1 | O28: 1 | P28: 1 | Q28: 1 | R28: 1 | S28: 结业
A29: 23 | B29: 22547 | C29: PANG TZE YINN | D29: 冯诗穎 | E29: PH | F29: S3B | H29: 1 | I29: 1 | J29: 1 | K29: 病假 | L29: 1 | M29: 1 | N29: 1 | O29: 1 | P29: 1 | Q29: 1 | R29: 1 | S29: 1 | T29: 1 | U29: 1 | V29: 1 | W29: 1 | X29: 1 | Y29: 1 | Z29: 1 | AA29: 1
A30: 24 | B30: 21520 | C30: OW KA EE | D30: 胡嘉钰 | E30: PH | F30: S3B | H30: 1 | I30: 1 | J30: 1 | K30: 1 | L30: 1 | M30: 1 | N30: 1 | O30: 1 | P30: 1 | Q30: 1 | R30: 1 | S30: 1 | T30: 1 | U30: 1 | V30: 1 | W30: 1 | X30: 1 | Y30: 1 | Z30: 1 | AA30: 病假
A31: 25 | B31: 21062 | C31: LIM ZHEN XIN | D31: 林正鑫 | E31: L | F31: S3B | H31: 1 | I31: 1 | J31: 1 | K31: 1 | L31: 1 | M31: 1 | N31: 1 | O31: 1 | P31: 1 | Q31: 1 | R31: 1 | S31: 1 | T31: 1 | U31: 1 | V31: 1 | W31: 1 | X31: 1 | Y31: 1 | Z31: 1 | AA31: 病假
A32: 26 | B32: 21021 | C32: CHAN JIE YEE | D32: 曾洁瑜 | E32: P | F32: S3B | H32: 1 | I32: 1 | J32: 1 | K32: 1 | L32: 1 | M32: 1 | N32: 1 | O32: 1 | P32: 1 | Q32: 1 | R32: 1 | S32: 1 | T32: 1 | U32: 1 | V32: 1 | W32: 1 | X32: 1 | Y32: 1 | Z32: 1 | AA32: 1
A33: 27 | B33: 21082 | C33: CHENG XIANG LIN | D33: 曾翔麟 | E33: L | F33: S3B | H33: 1 | I33: 1 | J33: 1 | K33: 1 | L33: 1 | M33: 1 | N33: 1 | O33: 结业
A34: 28 | B34: 21007 | C34: WONG YU ZHE | D34: 黄于哲 | E34: L | F34: S3B | H34: 1 | I34: 1 | J34: 1 | K34: 1 | L34: 1 | M34: 1 | N34: 1 | O34: 1 | P34: 1 | Q34: 1 | R34: 1 | S34: 1 | T34: 1 | U34: 1 | V34: 1 | W34: 1 | X34: 1 | Y34: 1 | Z34: 1 | AA34: 1
A35: 29 | B35: 21042 | C35: SIOW YU XUAN | D35: 萧宇瑄 | E35: P | F35: C3A | H35: 1 | I35: 1 | J35: 1 | K35: 1 | L35: 1 | M35: 1 | N35: 1 | O35: 1 | P35: 1 | Q35: 1 | R35: 1 | S35: 1 | T35: 1 | U35: 1 | V35: 1 | W35: 病假 | X35: 公假 | Y35: 1 | Z35: 1 | AA35: 1
A36: 30
A37: 31
A38: 32
A39: 33
A40: 34
...

Sheet U1A 美术-陈彩韵
A1: 科目： | C1: U1A美术 | H1: 男 | J1: 女
A2: 时段: | C2: ='选修课表清单'!E4 -> Thursday / 14:30~15:40 | G2: 走/宿 | H2: L | I2: LH | J2: P | K2: PH | L2: 总计
A3: 地点： | C3: ='选修课表清单'!F4 -> A406 | G3: 人数 | H3: =COUNTIF($E:$E,"L") -> 5 | I3: =COUNTIF($E:$E,"LH") -> 3 | J3: =COUNTIF($E:$E,"P") -> 6 | K3: =COUNTIF($E:$E,"PH") -> 2 | L3: =H4+J4 -> 16
A4: 老师： | C4: ='选修课表清单'!C4 -> 陈彩韵 | G4: 合计 | H4: =SUM(H3:I3) -> 8 | J4: =SUM(J3:K3) -> 8
H5: ⬇️ | I5: "Please start entering the class dates from cell H6."
A6: No. | B6: ADM. | C6: Name | D6: 姓名 | E6: 性别 | F6: 班级 | G6: 承诺书 | H6: 22/1 | I6: 29/1
A7: 1 | B7: 22174 | C7: TAN CHEE YANG | D7: 陈子洋 | E7: LH | F7: U1A | H7: 1
A8: 2 | B8: 22202 | C8: VINCENT KOW LEE WEI | D8: 高笠为 | E8: LH | F8: U1A | H8: 1
A9: 3 | B9: 23107 | C9: SHAM KEAN FOONG | D9: 覃健峰 | E9: LH | F9: U1A | H9: 1
A10: 4 | B10: 23181 | C10: OOI EJING | D10: 黄鈺晶 | E10: PH | F10: U1A | H10: 1
A11: 5 | B11: 23215 | C11: TEO HAOJIN | D11: 张皓竣 | E11: L | F11: U1A | H11: 1
A12: 6 | B12: 23247 | C12: LAI YU XUAN | D12: 赖妤璇 | E12: P | F12: U1A | H12: 1
A13: 7 | B13: 23297 | C13: TUNG KAI XUAN | D13: 邓恺萱 | E13: P | F13: U1A | H13: 1
A14: 8 | B14: 23352 | C14: CHONG ZHENG YAN | D14: 张津益 | E14: L | F14: U1A | H14: 1
A15: 9 | B15: 23365 | C15: THOO LI YUN | D15: 杜丽云 | E15: P | F15: U1A | H15: 1
A16: 10 | B16: 23387 | C16: VIVIAN HO XIN YE | D16: 何欣怡 | E16: PH | F16: U1A | H16: 1
A17: 11 | B17: 23468 | C17: YEE XIN RU | D17: 余欣洳 | E17: P | F17: U1A | H17: 1
A18: 12 | B18: 23507 | C18: CHENG ZHI HONG | D18: 曾子康 | E18: L | F18: U1A | H18: 1
... A22: 16 | B22: 26454 | C22: HUM WAI WENG | D22: 谭伟荣 | E22: L | F22: U1A | H22: 1
A23: 17
A24: 18
A25: 19
A26: 20
A27: 21
A28: 22
A29: 23
A30: 24
A31: 25
A32: 26
A33: 27
A34: 28
... A46: 40

Sheet 高一 SPM AddMath 温添发
A1: 科目： | C1: 高一 ADDMath | H1: 男 | J1: 女
A2: 时段: | C2: ='选修课表清单'!E8 -> Tuesday / 16:15~17:25 & Wednesday 16:15~17:25 | G2: 走/宿 | H2: L | I2: LH | J2: P | K2: PH | L2: 总计
A3: 地点： | C3: ='选修课表清单'!F8 -> A301 | G3: 人数 | H3: =COUNTIF($E:$E,"L") -> 7 | I3: =COUNTIF($E:$E,"LH") -> 9 | J3: =COUNTIF($E:$E,"P") -> 11 | K3: =COUNTIF($E:$E,"PH") -> 5 | L3: =H4+J4 -> 32
A4: 老师： | C4: ='选修课表清单'!C8 -> 温添发 | G4: 合计 | H4: =SUM(H3:I3) -> 16 | J4: =SUM(J3:K3) -> 16
H5: ⬇️ | I5: "Please start entering the class dates from cell H6."
A6: No. | B6: ADM. | C6: Name | D6: 姓名 | E6: 性别 | F6: 班级 | G6: 承诺书 | H6: 20/1 | I6: 21/1 | J6: 27/1 | K6: 28/1 | L6: 3/2 | M6: 4/2 | N6: 10/2 | O6: 11/2 | P6: 24/2 | Q6: 25/2 | R6: 3/3 | S6: 4/3 | T6: 31/3 | U6: 1/4
A7: 1 | B7: 23195 | C7: GAN JUN HONG | D7: 颜寯浤 | E7: LH | F7: AC1A | H7: 1 | I7: 1 | J7: 1 | K7: 1 | L7: 1 | M7: 1 | N7: 1 | O7: 1 | P7: 1 | Q7: 1 | R7: 1 | S7: 1 | T7: 1 | U7: 1
A8: 2 | B8: 23280 | C8: TENG WEN BIN | D8: 邓文彬 | E8: LH | F8: AC1A | H8: 1 | I8: 1 | J8: 1 | K8: 1 | L8: 1 | M8: 1 | N8: 1 | O8: 1 | P8: 1 | Q8: 1 | R8: 1 | S8: 1 | T8: 1 | U8: 1
A9: 3 | B9: 23029 | C9: CHEN JIA XIN | D9: 曾佳杏 | E9: P | F9: C1A | H9: 1 | I9: 1 | J9: 1 | K9: 1 | L9: 1 | M9: 1 | N9: 1 | O9: 1 | P9: 1 | Q9: 1 | R9: 1 | S9: 1 | T9: 1 | U9: 1
A10: 4 | B10: 23040 | C10: KHOO EE LIN | D10: 邱以琳 | E10: P | F10: C1A | H10: 1 | I10: 1 | J10: 1 | K10: 1 | L10: 1 | M10: 1 | N10: 1 | O10: 1 | P10: 1 | Q10: 1 | R10: 1 | S10: 1 | T10: 1 | U10: 1
A11: 5 | B11: 23056 | C11: SELINA LU SHI TING | D11: 卢诗婷 | E11: P | F11: C1A | H11: 1 | I11: 1 | J11: 1 | K11: 1 | L11: 1 | M11: 1 | N11: 1 | O11: 1 | P11: 1 | Q11: 1 | R11: 1 | S11: 1 | T11: 1 | U11: 1
A12: 6 | B12: 23068 | C12: YOU IE JEAN | D12: 余宜静 | E12: PH | F12: C1A | H12: 1 | I12: 1 | J12: 1 | K12: 1 | L12: 1 | M12: 1 | N12: 1 | O12: 1 | P12: 1 | Q12: 1 | R12: 1 | S12: 1 | T12: 1 | U12: 1
A13: 7 | B13: 23226 | C13: LOW CHEE HAO | D13: 刘子豪 | E13: LH | F13: C1A | H13: 1 | I13: 1 | J13: 1 | K13: 1 | L13: 1 | M13: 1 | N13: 1 | O13: 1 | P13: 1 | Q13: 1 | R13: 1 | S13: 1 | T13: 1 | U13: 1
A14: 8 | B14: 23238 | C14: WANG KAR WEI | D14: 王家玮 | E14: L | F14: C1A | H14: 1 | I14: 1 | J14: 1 | K14: 1 | L14: 1 | M14: 1 | N14: 1 | O14: 1 | P14: 1 | Q14: 1 | R14: 1 | S14: 1 | T14: 1 | U14: 1
A15: 9 | B15: 23377 | C15: SHAWN OOI JUN HAO | D15: 黄俊皓 | E15: L | F15: C1A | H15: 1 | I15: 1 | J15: 1 | K15: 1 | L15: 1 | M15: 1 | N15: 1 | O15: 1 | P15: 1 | Q15: 1 | R15: 1 | S15: 1 | T15: 1 | U15: 1
A16: 10 | B16: 23499 | C16: LIM ZHYI JACK | D16: 林资杰 | E16: LH | F16: C1A | H16: 1 | I16: 1 | J16: 1 | K16: 1 | L16: 1 | M16: 1 | N16: 1 | O16: 1 | P16: 1 | Q16: 1 | R16: 1 | S16: 1 | T16: 1 | U16: 1
A17: 11 | B17: 23012 | C17: CHOONG ZI YI | D17: 钟子怡 | E17: P | F17: C1B | H17: 1 | I17: 1 | J17: 1 | K17: 1 | L17: 1 | M17: 1 | N17: 1 | O17: 1 | P17: 1 | Q17: 1 | R17: 1 | S17: 1 | T17: 1 | U17: 1
A18: 12 | B18: 23018 | C18: WO JIA YING | D18: 胡珈郢 | E18: P | F18: C1B | H18: 1 | I18: 1 | J18: 1 | K18: 1 | L18: 1 | M18: 1 | N18: 1 | O18: 1 | P18: 1 | Q18: 1 | R18: M | S18: M | T18: 1 | U18: 1
A19: 13 | B19: 23030 | C19: THAM KAH JUN | D19: 覃嘉俊 | E19: LH | F19: C1B | H19: 1 | I19: 1 | J19: 1 | K19: 1 | L19: 1 | M19: 1 | N19: 1 | O19: 1 | P19: 1 | Q19: 1 | R19: 1 | S19: 1 | T19: 1 | U19: 1
A20: 14 | B20: 23045 | C20: TAN QING SHIN | D20: 陈晴心 | E20: P | F20: C1B | H20: 1 | I20: 1 | J20: 1 | K20: 1 | L20: 1 | M20: 1 | N20: 1 | O20: 1 | P20: 1 | Q20: 1 | R20: 1 | S20: 1 | T20: 1 | U20: 1
A21: 15 | B21: 23110 | C21: LIM ZHENG WEI | D21: 林政諱 | E21: LH | F21: C1B | H21: 1 | I21: 1 | J21: 1 | K21: 1 | L21: 1 | M21: 1 | N21: 1 | O21: 1 | P21: 1 | Q21: 1 | R21: 1 | S21: 1 | T21: 1 | U21: 1
A22: 16 | B22: 23115 | C22: XAVIER LAI GUAN QUAN | D22: 赖冠全 | E22: LH | F22: C1B | H22: 1 | I22: 1 | J22: 1 | K22: 1 | L22: 1 | M22: 1 | N22: 1 | O22: 1 | P22: 1 | Q22: 1 | R22: 1 | S22: 1 | T22: 1 | U22: 1
A23: 17 | B23: 23200 | C23: LEE ZI HIM | D23: 李子谦 | E23: L | F23: C1B | H23: 1 | I23: 1 | J23: 1 | K23: 1 | L23: 1 | M23: 1 | N23: 1 | O23: 1 | P23: 1 | Q23: 1 | R23: 1 | S23: 1 | T23: 1 | U23: 1
A24: 18 | B24: 23227 | C24: ONG KAH HENG | D24: 王家兴 | E24: LH | F24: C1B | H24: 1 | I24: 1 | J24: 1 | K24: 1 | L24: 1 | M24: 1 | N24: 1 | O24: 1 | P24: 1 | Q24: G | R24: 1 | S24: 1 | T24: 1 | U24: 1
A25: 19 | B25: 23242 | C25: LEE WYE KEI MIRACLE | D25: 李慰琦 | E25: PH | F25: C1B | H25: 1 | I25: 1 | J25: 1 | K25: 1 | L25: 1 | M25: 1 | N25: 1 | O25: 1 | P25: 1 | Q25: 1 | R25: M | S25: M | T25: 1 | U25: 1
A26: 20 | B26: 23272 | C26: LIM HUI LI | D26: 林慧丽 | E26: P | F26: C1B | H26: 1 | I26: 1 | J26: 1 | K26: 1 | L26: 1 | M26: 1 | N26: 1 | O26: M | P26: 1 | Q26: 1 | R26: 1 | S26: 1 | T26: 1 | U26: 1
A27: 21 | B27: 23342 | C27: KHOO MIN HUI | D27: 邱忞泋 | E27: P | F27: C1B | H27: 1 | I27: 1 | J27: 1 | K27: 1 | L27: 1 | M27: 1 | N27: 1 | O27: 1 | P27: 1 | Q27: 1 | R27: 1 | S27: 1 | T27: 1 | U27: 1
A28: 22 | B28: 23373 | C28: CHARLOTTE CHIN YU XUEN | D28: 陈瑜譞 | E28: P | F28: C1B | H28: 1 | I28: 1 | J28: 1 | K28: 1 | L28: 1 | M28: M | N28: 1 | O28: 1 | P28: 1 | Q28: 1 | R28: M | S28: M | T28: 1 | U28: 1
A29: 23 | B29: 23425 | C29: LAW ZI HUI | D29: 陆耔汇 | E29: PH | F29: C1B | H29: 1 | I29: 1 | J29: 1 | K29: 1 | L29: 1 | M29: 1 | N29: 1 | O29: 1 | P29: 1 | Q29: 1 | R29: 1 | S29: 1 | T29: 1 | U29: 1
A30: 24 | B30: 23451 | C30: TAN XIU LI | D30: 陈秀莉 | E30: PH | F30: C1B | H30: 1 | I30: 1 | J30: 1 | K30: 1 | L30: 1 | M30: 1 | N30: 1 | O30: 1 | P30: 1 | Q30: 1 | R30: 1 | S30: 1 | T30: 1 | U30: 1
A31: 25 | B31: 23553 | C31: YAP ZI YING | D31: 叶芷郢 | E31: P | F31: C1B | H31: 1 | I31: 1 | J31: 1 | K31: 1 | L31: 1 | M31: 1 | N31: 1 | O31: 1 | P31: 1 | Q31: G | R31: 1 | S31: 1 | T31: 1 | U31: 1
A32: 26 | B32: 23341 | C32: LEE JUN YUNG | D32: 李俊澭 | E32: LH | F32: C1C | H32: 1 | I32: 1 | J32: 1 | K32: 1 | L32: 1 | M32: 1 | N32: 1 | O32: 1 | P32: 1 | Q32: G | R32: 1 | S32: 1 | T32: 1 | U32: 1
A33: 27 | B33: 23441 | C33: IVAN YAM KEE ONN | D33: 任祈銨 | E33: L | F33: C1C | H33: 1 | I33: 1 | J33: 1 | K33: 1 | L33: 1 | M33: 1 | N33: 1 | O33: 1 | P33: 1 | Q33: 1 | R33: 1 | S33: 1 | T33: 1 | U33: 1
A34: 28 | B34: 23173 | C34: CHAN XIN NING | D34: 陈星宁 | E34: P | F34: C1E | H34: 1 | I34: 1 | J34: 1 | K34: 1 | L34: 1 | M34: 1 | N34: 1 | O34: 1 | P34: 1 | Q34: G | R34: 1 | S34: 1 | T34: 1 | U34: 1
A35: 29 | B35: 23417 | C35: CARRICK KAW ZHI JUN | D35: 邱子峻 | E35: L | F35: C1E | H35: 1 | I35: 1 | J35: 1 | K35: 1 | L35: 1 | M35: 1 | N35: 1 | O35: 1 | P35: 1 | Q35: G | R35: 1 | S35: 1 | T35: 1 | U35: 1
A36: 30 | B36: 23444 | C36: ALOYSIUS TAN ZHI KUAN | D36: 陈旨宽 | E36: L | F36: C1E | H36: 1 | I36: 1 | J36: 1 | K36: 1 | L36: 1 | M36: 1 | N36: 1 | O36: 1 | P36: 1 | Q36: 1 | R36: 1 | S36: 1 | T36: 1 | U36: 1
A37: 31 | B37: 23113 | C37: LIEW XIN YEE | D37: 刘馨怡 | E37: PH | F37: C1F | H37: 1/4/2026 从 S1B 转班到 C1F | U37: 1
A38: 32 | B38: 23170 | C38: TEO ZHI XIANG | D38: 张智翔 | E38: L | F38: C1F | H38: 1 | I38: 1 | J38: 1 | K38: 1 | L38: 1 | M38: 1 | N38: 1 | O38: 1 | P38: 1 | Q38: G | R38: 1 | S38: 1 | T38: 1 | U38: 1
A39: 33
A40: 34
...

Sheet 高一华文文学 曾奂焜
A1: 科目： | C1: 高一华文文学 | H1: 男 | J1: 女
A2: 时段: | C2: ='选修课表清单'!E5 -> Tuesday / 16:15~16:50 & Thursday / 15:40~16:50 | G2: 走/宿 | H2: L | I2: LH | J2: P | K2: PH | L2: 总计
A3: 地点： | C3: ='选修课表清单'!F5 -> A307 | G3: 人数 | H3: =COUNTIF($E:$E,"L") -> 7 | I3: =COUNTIF($E:$E,"LH") -> 6 | J3: =COUNTIF($E:$E,"P") -> 10 | K3: =COUNTIF($E:$E,"PH") -> 5 | L3: =H4+J4 -> 28
A4: 老师： | C4: ='选修课表清单'!C5 -> 曾奂焜 | G4: 合计 | H4: =SUM(H3:I3) -> 13 | J4: =SUM(J3:K3) -> 15
H5: ⬇️ | I5: "Please start entering the class dates from cell H6."
A6: No. | B6: ADM. | C6: Name | D6: 姓名 | E6: 性别 | F6: 班级 | G6: 承诺书 | H6: 20/1 | I6: 22/1 | J6: 27/1 | K6: 29/1 | L6: 3/2 | M6: 5/2 | N6: 10/2 | O6: 12/2 | P6: 24/2 | Q6: 26/2 | R6: 3/3 | S6: 5/3 | T6: 31/3 | U6: 2/4 | V6: 7/4 | W6: 9/4 | X6: 14/4 | Y6: 16/4 | Z6: 21/4 | AA6: 23/4 | AB6: 28/4 | AC6: 30/4 | AD6: 5/5 | AE6: 7/5 | AF6: 12/5 | AG6: 9/6 | AH6: 11/6 | AI6: 16/6 | AJ6: 18/6 | AK6: 23/6 | AL6: 25/6 | AM6: 30/6 | AN6: 2/7 | AO6: 9/7 | AP6: 14/7 | AQ6: 16/7 | AR6: 21/7 | AS6: 23/7 | AT6: 27/7 | AU6: 30/7 | AV6: 4/8 | AW6: 6/8 | AX6: 11/8 | AY6: 13/8 | AZ6: 20/8 | BA6: 25/8 | BB6: 8/9 | BC6: 10/9 | BD6: 15/9 | BE6: 17/9 | BF6: 22/9 | BG6: 24/9 | BH6: 29/9
A7: 1 | B7: 23037 | C7: LEE DI MING | D7: 李迪銘 | E7: LH | F7: S1A | H7: 1 | I7: 1 | J7: 1 | K7: 1 | L7: 1 | M7: 1 | N7: 1 | O7: 1 | P7: 1 | Q7: 1 | R7: 1 | S7: 1 | T7: 1 | U7: G | V7: 1 | W7: 1 | X7: 1 | Y7: 1 | Z7: 1 | AA7: 1 | AB7: 1 | AC7: 1 | AD7: 1 | AE7: 1 | AF7: 1 | AG7: 1 | AH7: 1 | AI7: 1 | AJ7: 1 | AK7: 1 | AL7: 1 | AM7: 1 | AN7: 1 | AO7: 1 | AP7: 1 | AQ7: 1 | AR7: 1 | AS7: 1 | AT7: 1 | AU7: 1 | AV7: 1 | AW7: 1 | AX7: 1 | AY7: 1 | AZ7: 1 | BA7: 1 | BB7: 1 | BC7: 1 | BD7: 1 | BE7: 1 | BF7: 1 | BG7: 1 | BH7: 1
A8: 2 | B8: 23097 | C8: CHEN SHUN QUAN | D8: 曾顺泉 | E8: LH | F8: S1A | H8: 1 | I8: 1 | J8: 1 | K8: 1 | L8: 1 | M8: 1 | N8: 1 | O8: 1 | P8: 1 | Q8: 1 | R8: 1 | S8: 1 | T8: 1 | U8: 1 | V8: 1 | W8: 1 | X8: 1 | Y8: 1 | Z8: 1 | AA8: 1 | AB8: 1 | AC8: 1 | AD8: 1 | AE8: 1 | AF8: 1 | AG8: 1 | AH8: 1 | AI8: 1 | AJ8: 1 | AK8: 1 | AL8: 1 | AM8: 1 | AN8: 1 | AO8: 1 | AP8: 1 | AQ8: 1 | AR8: 1 | AS8: 1 | AT8: 1 | AU8: 1 | AV8: 1 | AW8: 1 | AX8: 1 | AY8: 1 | AZ8: 1 | BA8: 1 | BB8: 1 | BC8: 1 | BD8: 1 | BE8: 1 | BF8: 1 | BG8: 1 | BH8: 1
A9: 3 | B9: 23353 | C9: LEE JUN YIT | D9: 吕俊毅 | E9: L | F9: C1E | H9: 1 | I9: 1 | J9: 1 | K9: 1 | L9: 1 | M9: 1 | N9: 1 | O9: 1 | P9: 1 | Q9: 1 | R9: 1 | S9: 1 | T9: 1 | U9: 1 | V9: 1 | W9: 1 | X9: 1 | Y9: 1 | Z9: 1 | AA9: 1 | AB9: 1 | AC9: 1 | AD9: 1 | AE9: 1 | AF9: 1 | AG9: 1 | AH9: 1 | AI9: 1 | AJ9: 1 | AK9: 1 | AL9: 1 | AM9: 1 | AN9: 1 | AO9: 1 | AP9: 1 | AQ9: 1 | AR9: 1 | AS9: 1 | AT9: 1 | AU9: 1 | AV9: 1 | AW9: 1 | AX9: 1 | AY9: 1 | AZ9: 1 | BA9: 1 | BB9: 1 | BC9: 1 | BD9: 1 | BE9: 1 | BF9: 1 | BG9: 1 | BH9: 1
A10: 4 | B10: 23033 | C10: ANGELA LEE SI EN | D10: 李思恩 | E10: P | F10: S1B | H10: 1 | I10: 1 | J10: 1 | K10: 1 | L10: 1 | M10: 1 | N10: 1 | O10: 1 | P10: 1 | Q10: 1 | R10: 1 | S10: 1 | T10: 1 | U10: 1 | V10: 1 | W10: 1 | X10: 1 | Y10: 1 | Z10: 1 | AA10: 1 | AB10: 1 | AC10: 1 | AD10: 1 | AE10: 1 | AF10: 1 | AG10: 1 | AH10: 1 | AI10: 1 | AJ10: 1 | AK10: 1 | AL10: 1 | AM10: 1 | AN10: 1 | AO10: 1 | AP10: 1 | AQ10: 1 | AR10: 1 | AS10: 1 | AT10: 1 | AU10: 1 | AV10: 1 | AW10: 1 | AX10: 1 | AY10: 1 | AZ10: 1 | BA10: 1 | BB10: 1 | BC10: 1 | BD10: 1 | BE10: 1 | BF10: 1 | BG10: 1 | BH10: 1
A11: 5 | B11: 23079 | C11: LEE YEN SIM | D11: 李彦心 | E11: P | F11: AC1A | H11: 1 | I11: 1 | J11: 1 | K11: 1 | L11: 1 | M11: 1 | N11: 1 | O11: 1 | P11: 1 | Q11: 1 | R11: 1 | S11: 1 | T11: 1 | U11: 1 | V11: 1 | W11: 1 | X11: 1 | Y11: 1 | Z11: 1 | AA11: 1 | AB11: 1 | AC11: 1 | AD11: 1 | AE11: 1 | AF11: 1 | AG11: 1 | AH11: 1 | AI11: 1 | AJ11: 1 | AK11: 1 | AL11: 1 | AM11: 1 | AN11: 1 | AO11: 1 | AP11: 1 | AQ11: 1 | AR11: 1 | AS11: 1 | AT11: 1 | AU11: 1 | AV11: 1 | AW11: 1 | AX11: 1 | AY11: 1 | AZ11: 1 | BA11: 1 | BB11: 1 | BC11: 1 | BD11: 1 | BE11: 1 | BF11: 1 | BG11: 1 | BH11: 1
A12: 6 | B12: 23087 | C12: TENG WAN SIM | D12: 汤婉心 | E12: P | F12: AC1A | H12: 1 | I12: 1 | J12: 1 | K12: 1 | L12: 1 | M12: 1 | N12: 1 | O12: 1 | P12: 1 | Q12: 1 | R12: 1 | S12: 1 | T12: 1 | U12: 0 | V12: 1 | W12: 0 | X12: 1 | Y12: 1 | Z12: 0 | AA12: 0 | AB12: 1 | AC12: 1 | AD12: 1 | AE12: 1 | AF12: 1 | AG12: 1 | AH12: 1 | AI12: 0 | AJ12: 1 | AK12: 1 | AL12: 1 | AM12: 1 | AN12: 1 | AO12: 1 | AP12: 1 | AQ12: 1 | AR12: 1 | AS12: 1 | AT12: 1 | AU12: 1 | AV12: 1 | AW12: 1 | AX12: 1 | AY12: 1 | AZ12: 1 | BA12: 1 | BB12: 1 | BC12: 1 | BD12: 1 | BE12: 1 | BF12: 1 | BG12: 1 | BH12: 1
A13: 7 | B13: 23142 | C13: LEE XIN YEE | D13: 李芯億 | E13: PH | F13: AC1A | H13: 1 | I13: 1 | J13: 1 | K13: 1 | L13: 1 | M13: 1 | N13: 1 | O13: 1 | P13: 1 | Q13: 1 | R13: 1 | S13: 1 | T13: 1 | U13: 1 | V13: 1 | W13: 0 | X13: 1 | Y13: 1 | Z13: 1 | AA13: 1 | AB13: 1 | AC13: 1 | AD13: 1 | AE13: 1 | AF13: 1 | AG13: 1 | AH13: 1 | AI13: 1 | AJ13: 1 | AK13: 1 | AL13: 1 | AM13: 1 | AN13: 1 | AO13: 1 | AP13: 1 | AQ13: 1 | AR13: 1 | AS13: 1 | AT13: 1 | AU13: 1 | AV13: 1 | AW13: 1 | AX13: 1 | AY13: 1 | AZ13: 1 | BA13: 1 | BB13: 1 | BC13: 1 | BD13: 1 | BE13: 1 | BF13: 1 | BG13: 1 | BH13: 1
A14: 8 | B14: 23147 | C14: CHOO ZI YU | D14: 朱紫瑜 | E14: PH | F14: AC1A | H14: 1 | I14: 1 | J14: 1 | K14: 1 | L14: 1 | M14: 1 | N14: 1 | O14: 1 | P14: 1 | Q14: 1 | R14: 1 | S14: 1 | T14: 1 | U14: 1 | V14: 1 | W14: 1 | X14: 1 | Y14: 1 | Z14: 1 | AA14: 1 | AB14: 1 | AC14: 1 | AD14: 1 | AE14: 1 | AF14: 1 | AG14: 1 | AH14: 1 | AI14: 1 | AJ14: 1 | AK14: 1 | AL14: 1 | AM14: 1 | AN14: 1 | AO14: 1 | AP14: 1 | AQ14: 1 | AR14: 1 | AS14: 1 | AT14: 1 | AU14: 1 | AV14: 1 | AW14: 1 | AX14: 1 | AY14: 1 | AZ14: 1 | BA14: 1 | BB14: 1 | BC14: 1 | BD14: 1 | BE14: 1 | BF14: 1 | BG14: 1 | BH14: 1
A15: 9 | B15: 23149 | C15: CHIN EN YONG | D15: 陈恩詠 | E15: PH | F15: AC1A | H15: 1 | I15: 1 | J15: 1 | K15: 1 | L15: 1 | M15: 1 | N15: 1 | O15: 1 | P15: 1 | Q15: 1 | R15: 1 | S15: 1 | T15: 1 | U15: 1 | V15: 1 | W15: 1 | X15: 1 | Y15: 1 | Z15: 1 | AA15: 1 | AB15: 1 | AC15: 1 | AD15: 1 | AE15: 1 | AF15: 1 | AG15: 1 | AH15: 1 | AI15: 1 | AJ15: 1 | AK15: 1 | AL15: 1 | AM15: 1 | AN15: 1 | AO15: 1 | AP15: 1 | AQ15: 1 | AR15: 1 | AS15: 1 | AT15: 1 | AU15: 1 | AV15: 1 | AW15: 1 | AX15: 1 | AY15: 1 | AZ15: 1 | BA15: 1 | BB15: 1 | BC15: 1 | BD15: 1 | BE15: 1 | BF15: 1 | BG15: 1 | BH15: 1
A16: 10 | B16: 23266 | C16: NG KAI YANG | D16: 黄楷洋 | E16: L | F16: AC1A | H16: 1 | I16: 1 | J16: 1 | K16: 1 | L16: 1 | M16: 1 | N16: 1 | O16: 1 | P16: 1 | Q16: 1 | R16: 1 | S16: 1 | T16: 1 | U16: 1 | V16: 1 | W16: 1 | X16: 1 | Y16: 1 | Z16: 1 | AA16: 1 | AB16: 1 | AC16: 1 | AD16: 1 | AE16: 1 | AF16: 1 | AG16: 1 | AH16: 1 | AI16: 1 | AJ16: 1 | AK16: 1 | AL16: 1 | AM16: 1 | AN16: 1 | AO16: 1 | AP16: 1 | AQ16: 1 | AR16: 1 | AS16: 1 | AT16: 1 | AU16: 1 | AV16: 1 | AW16: 1 | AX16: 1 | AY16: 1 | AZ16: M | BA16: 1 | BB16: 1 | BC16: 1 | BD16: 1 | BE16: 1 | BF16: 1 | BG16: 1 | BH16: 1
A17: 11 | B17: 23267 | C17: CHEE MING XUAN | D17: 朱铭轩 | E17: L | F17: AC1A | H17: 1 | I17: 1 | J17: 1 | K17: 1 | L17: 1 | M17: 1 | N17: 1 | O17: 1 | P17: 1 | Q17: 1 | R17: 1 | S17: 1 | T17: 1 | U17: 1 | V17: 1 | W17: 1 | X17: 1 | Y17: 1 | Z17: 1 | AA17: 1 | AB17: 1 | AC17: 1 | AD17: 1 | AE17: 1 | AF17: 1 | AG17: 1 | AH17: 1 | AI17: 1 | AJ17: 1 | AK17: 1 | AL17: 1 | AM17: 1 | AN17: 1 | AO17: 1 | AP17: 1 | AQ17: 1 | AR17: 1 | AS17: 1 | AT17: 1 | AU17: 1 | AV17: 1 | AW17: 1 | AX17: 1 | AY17: 1 | AZ17: 1 | BA17: 1 | BB17: 1 | BC17: 1 | BD17: 1 | BE17: 1 | BF17: 1 | BG17: 1 | BH17: 1
A18: 12 | B18: 23412 | C18: YEK ZEH SHEN | D18: 叶泽渗 | E18: L | F18: AC1A | H18: 1 | I18: 1 | J18: 1 | K18: 1 | L18: 1 | M18: 1 | N18: 1 | O18: 1 | P18: 1 | Q18: 1 | R18: 1 | S18: 1 | T18: 1 | U18: 1 | V18: 1 | W18: 1 | X18: 1 | Y18: 1 | Z18: 1 | AA18: 1 | AB18: M | AC18: 1 | AD18: 1 | AE18: 1 | AF18: 1 | AG18: 1 | AH18: 1 | AI18: 1 | AJ18: 1 | AK18: 1 | AL18: 1 | AM18: 1 | AN18: 1 | AO18: 1 | AP18: M | AQ18: 1 | AR18: 1 | AS18: 1 | AT18: 1 | AU18: 1 | AV18: 1 | AW18: 1 | AX18: 1 | AY18: 1 | AZ18: 1 | BA18: 1 | BB18: 1 | BC18: 1 | BD18: 1 | BE18: 1 | BF18: 1 | BG18: 1 | BH18: 1
A19: 13 | B19: 23421 | C19: KAN ZI JUN | D19: 简子峻 | E19: L | F19: AC1A | H19: 1 | I19: 1 | J19: 1 | K19: 1 | L19: 1 | M19: 1 | N19: 1 | O19: 1 | P19: 1 | Q19: 1 | R19: 1 | S19: 1 | T19: 1 | U19: 1 | V19: 1 | W19: 1 | X19: 1 | Y19: 1 | Z19: 1 | AA19: 1 | AB19: 1 | AC19: 1 | AD19: 1 | AE19: 1 | AF19: 1 | AG19: 1 | AH19: 1 | AI19: 1 | AJ19: 1 | AK19: 1 | AL19: 1 | AM19: 1 | AN19: 1 | AO19: 1 | AP19: 1 | AQ19: 1 | AR19: 1 | AS19: 1 | AT19: 1 | AU19: 1 | AV19: 1 | AW19: 1 | AX19: 1 | AY19: 1 | AZ19: 1 | BA19: 1 | BB19: 1 | BC19: 1 | BD19: 1 | BE19: 1 | BF19: 1 | BG19: 1 | BH19: 1
A20: 14 | B20: 23044 | C20: LAM HUI WEN | D20: 林慧雯 | E20: P | F20: C1A | H20: 1 | I20: 1 | J20: 1 | K20: 1 | L20: 1 | M20: 1 | N20: 1 | O20: 1 | P20: 1 | Q20: 1 | R20: 1 | S20: 1 | T20: 1 | U20: 1 | V20: 1 | W20: 1 | X20: 1 | Y20: 1 | Z20: 1 | AA20: 1 | AB20: 1 | AC20: 1 | AD20: 1 | AE20: 1 | AF20: 1 | AG20: 1 | AH20: 1 | AI20: 1 | AJ20: 1 | AK20: 1 | AL20: 1 | AM20: 1 | AN20: 1 | AO20: 1 | AP20: 1 | AQ20: 1 | AR20: 1 | AS20: 1 | AT20: 1 | AU20: 1 | AV20: 1 | AW20: 1 | AX20: 1 | AY20: 1 | AZ20: 1 | BA20: 1 | BB20: 1 | BC20: 1 | BD20: 1 | BE20: 1 | BF20: 1 | BG20: 1 | BH20: 1
A21: 15 | B21: 23317 | C21: JEROME LIM JUN HAN | D21: 林君翰 | E21: L | F21: C1A | H21: 1 | I21: 1 | J21: 1 | K21: 1 | L21: 1 | M21: 1 | N21: 1 | O21: 1 | P21: 1 | Q21: 1 | R21: 1 | S21: 1 | T21: 0 | U21: 0 | V21: 1 | W21: 1 | X21: 1 | Y21: 1 | Z21: 1 | AA21: 1 | AB21: 1 | AC21: 1 | AD21: 1 | AE21: 1 | AF21: 1 | AG21: 1 | AH21: 1 | AI21: 1 | AJ21: 1 | AK21: 1 | AL21: 1 | AM21: 1 | AN21: 1 | AO21: 1 | AP21: 1 | AQ21: 1 | AR21: 1 | AS21: 1 | AT21: 1 | AU21: 1 | AV21: 1 | AW21: 1 | AX21: 1 | AY21: 1 | AZ21: 1 | BA21: 1 | BB21: 0 | BC21: 1 | BD21: 1 | BE21: 1 | BF21: 1 | BG21: 1 | BH21: 1
A22: 16 | B22: 23004 | C22: CHONG CHEE LAM | D22: 张子琳 | E22: PH | F22: C1B | H22: 1 | I22: 1 | J22: 1 | K22: 1 | L22: 1 | M22: 1 | N22: 1 | O22: 1 | P22: 1 | Q22: 1 | R22: 1 | S22: 1 | T22: 1 | U22: 1 | V22: 1 | W22: 1 | X22: 1 | Y22: 1 | Z22: 1 | AA22: 1 | AB22: 1 | AC22: 1 | AD22: 1 | AE22: 1 | AF22: 1 | AG22: 1 | AH22: 1 | AI22: 1 | AJ22: 1 | AK22: 1 | AL22: 1 | AM22: 1 | AN22: 1 | AO22: 1 | AP22: 1 | AQ22: 1 | AR22: 1 | AS22: 1 | AT22: 1 | AU22: 1 | AV22: 1 | AW22: 1 | AX22: 1 | AY22: G | AZ22: 1 | BA22: 1 | BB22: 1 | BC22: G | BD22: 1 | BE22: 1 | BF22: 1 | BG22: 1 | BH22: 1
A23: 17 | B23: 23013 | C23: LEE WEI TENG | D23: 吕尉婷 | E23: P | F23: C1B | H23: 1 | I23: 1 | J23: 1 | K23: 1 | L23: 1 | M23: 1 | N23: 1 | O23: 1 | P23: 1 | Q23: 1 | R23: 1 | S23: 1 | T23: 1 | U23: 1 | V23: 1 | W23: 1 | X23: 1 | Y23: 1 | Z23: 1 | AA23: 1 | AB23: 1 | AC23: 1 | AD23: 1 | AE23: 1 | AF23: 1 | AG23: 1 | AH23: 1 | AI23: 0 | AJ23: 1 | AK23: 1 | AL23: 1 | AM23: 1 | AN23: 1 | AO23: 1 | AP23: 1 | AQ23: 1 | AR23: 1 | AS23: 1 | AT23: 1 | AU23: 1 | AV23: 1 | AW23: 1 | AX23: 1 | AY23: 1 | AZ23: 1 | BA23: 1 | BB23: 1 | BC23: G | BD23: 1 | BE23: 0 | BF23: 1 | BG23: 1 | BH23: 1
A24: 18 | B24: 23253 | C24: BENTLEY LAW AO BING | D24: 廖傲彬 | E24: LH | F24: C1B | H24: 1 | I24: 1 | J24: 1 | K24: 1 | L24: 1 | M24: 1 | N24: 1 | O24: 1 | P24: 1 | Q24: 1 | R24: 1 | S24: 1 | T24: 1 | U24: 1 | V24: 1 | W24: 1 | X24: 1 | Y24: 1 | Z24: 1 | AA24: 1 | AB24: 1 | AC24: 1 | AD24: 1 | AE24: 1 | AF24: 1 | AG24: 1 | AH24: 1 | AI24: 1 | AJ24: 1 | AK24: 1 | AL24: 1 | AM24: 1 | AN24: 1 | AO24: 1 | AP24: 1 | AQ24: 1 | AR24: 1 | AS24: 1 | AT24: 1 | AU24: 1 | AV24: 1 | AW24: 1 | AX24: 1 | AY24: 1 | AZ24: 1 | BA24: 1 | BB24: 1 | BC24: 1 | BD24: 1 | BE24: 1 | BF24: 1 | BG24: 1 | BH24: 1
A25: 19 | B25: 23474 | C25: CHOO WENG HUEEN | D25: 朱泳萱 | E25: P | F25: C1B | H25: 1 | I25: 1 | J25: 1 | K25: 1 | L25: 1 | M25: 1 | N25: 1 | O25: 0 | P25: 1 | Q25: 1 | R25: 1 | S25: 1 | T25: 0 | U25: 0 | V25: 0 | W25: 1 | X25: 1 | Y25: 1 | Z25: 1 | AA25: 1 | AB25: 1 | AC25: 1 | AD25: 1 | AE25: 1 | AF25: 1 | AG25: 0 | AH25: 0 | AI25: 1 | AJ25: 1 | AK25: 1 | AL25: 1 | AM25: 1 | AN25: 1 | AO25: 1 | AP25: 1 | AQ25: 1 | AR25: 1 | AS25: 1 | AT25: 1 | AU25: 1 | AV25: 1 | AW25: 1 | AX25: 1 | AY25: 1 | AZ25: 1 | BA25: 1 | BB25: 1 | BC25: G | BD25: 1 | BE25: 1 | BF25: 1 | BG25: 1 | BH25: 1
A26: 20 | B26: 23139 | C26: TAN GONG XUN | D26: 陈功勋 | E26: LH | F26: C1C | H26: 1 | I26: 1 | J26: 1 | K26: 1 | L26: 1 | M26: 1 | N26: 1 | O26: 1 | P26: 1 | Q26: 1 | R26: 1 | S26: 1 | T26: 1 | U26: 1 | V26: 1 | W26: 1 | X26: 1 | Y26: 1 | Z26: G | AA26: 1 | AB26: 1 | AC26: 1 | AD26: 1 | AE26: 1 | AF26: 1 | AG26: 1 | AH26: 1 | AI26: 1 | AJ26: 1 | AK26: 1 | AL26: 1 | AM26: 1 | AN26: 1 | AO26: 1 | AP26: 1 | AQ26: 1 | AR26: 1 | AS26: 1 | AT26: 1 | AU26: 1 | AV26: 1 | AW26: 1 | AX26: 1 | AY26: 1 | AZ26: 1 | BA26: 1 | BB26: 1 | BC26: 1 | BD26: 1 | BE26: 1 | BF26: 1 | BG26: 1 | BH26: 1
A27: 21 | B27: 23311 | C27: CHONG KWOK JIN | D27: 莊寬進 | E27: L | F27: C1C | H27: 1 | I27: 1 | J27: 1 | K27: 1 | L27: 1 | M27: 1 | N27: 1 | O27: 1 | P27: 1 | Q27: 1 | R27: 1 | S27: 1 | T27: 1 | U27: 1 | V27: 1 | W27: 1 | X27: 1 | Y27: 1 | Z27: 1 | AA27: 1 | AB27: 1 | AC27: 1 | AD27: 1 | AE27: 1 | AF27: 1 | AG27: 1 | AH27: 1 | AI27: 1 | AJ27: 1 | AK27: 1 | AL27: 1 | AM27: 1 | AN27: 1 | AO27: 1 | AP27: 1 | AQ27: 1 | AR27: 1 | AS27: 1 | AT27: 1 | AU27: 1 | AV27: 1 | AW27: 1 | AX27: 1 | AY27: 1 | AZ27: 1 | BA27: 1 | BB27: 1 | BC27: 1 | BD27: 1 | BE27: 1 | BF27: 1 | BG27: 1 | BH27: 1
A28: 22 | B28: 23088 | C28: PAN HUI XIN | D28: 范惠欣 | E28: PH | F28: C1D | H28: 1 | I28: 1 | J28: 1 | K28: 1 | L28: 1 | M28: 1 | N28: 1 | O28: 1 | P28: 1 | Q28: 1 | R28: 1 | S28: 1 | T28: 1 | U28: 1 | V28: G | W28: 1 | X28: 1 | Y28: 1 | Z28: 1 | AA28: 1 | AB28: 0 | AC28: 1 | AD28: 1 | AE28: 1 | AF28: 1 | AG28: 1 | AH28: 0 | AI28: 1 | AJ28: 1 | AK28: 1 | AL28: 1 | AM28: 1 | AN28: 1 | AO28: 1 | AP28: 1 | AQ28: 1 | AR28: 1 | AS28: 1 | AT28: 1 | AU28: 1 | AV28: 1 | AW28: 1 | AX28: 1 | AY28: 1 | AZ28: 1 | BA28: 1 | BB28: 1 | BC28: 1 | BD28: 1 | BE28: 1 | BF28: 1 | BG28: 1 | BH28: 1
A29: 23 | B29: 23225 | C29: MAX ONG QI LONG | D29: 王启笼 | E29: LH | F29: C1E | H29: 1 | I29: 1 | J29: 1 | K29: 1 | L29: 1 | M29: 1 | N29: 1 | O29: 1 | P29: 1 | Q29: 1 | R29: 1 | S29: 1 | T29: 1 | U29: 1 | V29: 1 | W29: 1 | X29: 1 | Y29: 1 | Z29: 1 | AA29: 1 | AB29: 1 | AC29: 1 | AD29: 1 | AE29: 1 | AF29: 1 | AG29: 1 | AH29: 1 | AI29: 0 | AJ29: 1 | AK29: 1 | AL29: 1 | AM29: 1 | AN29: 1 | AO29: 1 | AP29: 1 | AQ29: 1 | AR29: 1 | AS29: 1 | AT29: 1 | AU29: 1 | AV29: 1 | AW29: 0 | AX29: 0 | AY29: 1 | AZ29: 1 | BA29: 1 | BB29: 1 | BC29: 1 | BD29: 1 | BE29: 1 | BF29: 1 | BG29: 1 | BH29: 1
A30: 24 | B30: 23207 | C30: CHING LIK HUNG | D30: 曾令丰 | E30: LH | F30: C1F | H30: 1 | I30: 1 | J30: 1 | K30: 1 | L30: 1 | M30: 1 | N30: 1 | O30: 1 | P30: 1 | Q30: 1 | R30: 1 | S30: 1 | T30: 1 | U30: 1 | V30: 1 | W30: 1 | X30: 1 | Y30: 1 | Z30: 1 | AA30: 1 | AB30: 1 | AC30: 1 | AD30: 1 | AE30: 1 | AF30: 1 | AG30: 1 | AH30: 1 | AI30: 1 | AJ30: 1 | AK30: 0 | AL30: 1 | AM30: 1 | AN30: 1 | AO30: 1 | AP30: 1 | AQ30: 1 | AR30: 1 | AS30: 1 | AT30: 1 | AU30: 1 | AV30: 1 | AW30: 1 | AX30: 1 | AY30: 1 | AZ30: 1 | BA30: 1 | BB30: 1 | BC30: 1 | BD30: 1 | BE30: 1 | BF30: 1 | BG30: 1 | BH30: 1
A31: 25 | B31: 23369 | C31: LEE ZI NING | D31: 李紫宁 | E31: P | F31: C1F | H31: 1 | I31: 1 | J31: 1 | K31: 1 | L31: 1 | M31: 1 | N31: 1 | O31: 1 | P31: 1 | Q31: 1 | R31: 1 | S31: 1 | T31: 1 | U31: 1 | V31: M | W31: 1 | X31: 1 | Y31: 1 | Z31: 1 | AA31: 1 | AB31: 1 | AC31: 1 | AD31: M | AE31: 1 | AF31: 1 | AG31: 1 | AH31: 1 | AI31: 1 | AJ31: 1 | AK31: 1 | AL31: 1 | AM31: 1 | AN31: 1 | AO31: 1 | AP31: 1 | AQ31: 1 | AR31: 1 | AS31: 1 | AT31: 1 | AU31: 1 | AV31: M | AW31: 1 | AX31: 1 | AY31: 1 | AZ31: 1 | BA31: 1 | BB31: 1 | BC31: 1 | BD31: 1 | BE31: 1 | BF31: 1 | BG31: 1 | BH31: 1
